<?xml version="1.0" ?>
<!-- =================================================================================== -->
<!-- |    This document was autogenerated by xacro from /home/artuser/catkin_ws/src/artros/aist_description/scenes/urdf/fvision_base_scene.urdf.xacro | -->
<!-- |    EDITING THIS FILE BY HAND IS NOT RECOMMENDED                                 | -->
<!-- =================================================================================== -->
<robot name="fvision_base_scene">
    <!-- This is the main file defining our robot arrangement and physical environment. -->
    <!-- Main workspace -->
    <!-- The surface is 0.01 m below the robot bases and the "workspace_center" frame. -->
    <link name="ground" />
    <!-- This creates a box with the origin in the bottom corner, fixed to the world link. -->
    <link name="workbox">
        <!-- w is in x, l is in y, h is in z -->
        <visual>
            <origin rpy="0 0 0" xyz="0.45 0.375 0.005" />
            <geometry>
                <box size="0.9 0.75 0.01" />
            </geometry>
            <material name="Grey">
                <color rgba="0.7 0.7 0.7 1" />
            </material>
        </visual>
        <collision>
            <origin rpy="0 0 0" xyz="0.45 0.375 0.005" />
            <geometry>
                <box size="0.9 0.75 0.01" />
            </geometry>
        </collision>
        <!-- This is required for Gazebo. -->
        <inertial>
            <mass value="1.0" />
            <!-- <origin xyz="${width/2} ${length} ${height/2}" rpy="0 0 0"/> -->
            <inertia ixx="0.0" ixy="0.0" ixz="0.0" iyy="0.0" iyz="0.0" izz="0.0" />
            <origin xyz="0 0 0" rpy="0 0 0" />
        </inertial>
    </link>
    <gazebo reference="workbox">
        <material>Gazebo/Grey</material>
        <plugin name="gazebo_ros_control">
            <robotNamespace>/</robotNamespace>
        </plugin>
    </gazebo>
    <joint name="workbox" type="fixed">
        <parent link="ground" />
        <child link="workbox" />
        <origin rpy="0 0 0" xyz="-0.45 -0.375 0.76" />
    </joint>
    <link name="workspace_center" />
    <joint name="ground_to_workspace" type="fixed">
        <parent link="ground" />
        <child link="workspace_center" />
        <origin rpy="0 0 0" xyz="0 0 0.77" />
    </joint>
    <!--
    Main xacro macro definition of the "Gazebo robot" model.

    This wraps the model of the real robot and adds all elements and parameters
    required by Gazebo.

    It also adds the gazebo_ros_control plugin.

    NOTE: this is NOT a URDF. It cannot directly be loaded by consumers
    expecting a flattened '.urdf' file. See the top-level '.xacro' for that
    (but note: that .xacro must still be processed by the xacro command).

    For use in '.launch' files: use one of the 'load_urX.launch' convenience
    launch files.

    NOTE: this Gazebo model makes use of the same set of parameter files as the
    main xacro macro (in ur_description). It is therefor possible to use the
    kinematic calibration exported from a REAL UR robot. Please refer to the
    ur_macro.xacro in ur_description for more information about this.

    Main author of the migration to yaml configs: Ludovic Delval.

    Contributors to previous versions (in no particular order):

     - Felix Messmer
     - Kelsey Hawkins
     - Shaun Edwards
     - Alexander Bubeck
     - Nadia Hammoudeh Garcia
     - G. vd. Hoorn
     - Dave Niewinski
     - Andy Zelenak
     - Miguel Prada
     - Mathias Luedtke
     - Hans-Joachim Krauch
     - Felix Exner
  -->
    <!--
    Base UR robot series xacro macro.

    NOTE: this is NOT a URDF. It cannot directly be loaded by consumers
    expecting a flattened '.urdf' file. See the top-level '.xacro' for that
    (but note: that .xacro must still be processed by the xacro command).

    For use in '.launch' files: use one of the 'load_urX.launch' convenience
    launch files.

    This file models the base kinematic chain of a UR robot, which then gets
    parameterised by various configuration files to convert it into a UR3(e),
    UR5(e), UR10(e) or UR16e.

    NOTE: the default kinematic parameters (ie: link lengths, frame locations,
    offets, etc) do not correspond to any particular robot. They are defaults
    only. There WILL be non-zero offsets between the Forward Kinematics results
    in TF (ie: robot_state_publisher) and the values reported by the Teach
    Pendant.

    For accurate (and robot-specific) transforms, the 'kinematics_parameters_file'
    parameter MUST point to a .yaml file containing the appropriate values for
    the targetted robot.

    If using the UniversalRobots/Universal_Robots_ROS_Driver, follow the steps
    described in the readme of that repository to extract the kinematic
    calibration from the controller and generate the required .yaml file.

    Main author of the migration to yaml configs: Ludovic Delval.

    Contributors to previous versions (in no particular order):

     - Felix Messmer
     - Kelsey Hawkins
     - Wim Meeussen
     - Shaun Edwards
     - Nadia Hammoudeh Garcia
     - Dave Hershberger
     - G. vd. Hoorn
     - Philip Long
     - Dave Coleman
     - Miguel Prada
     - Mathias Luedtke
     - Marcel Schnirring
     - Felix von Drigalski
     - Felix Exner
     - Jimmy Da Silva
     - Ajit Krisshna N L
     - Muhammad Asif Rana
  -->
    <!--
    NOTE: the macro defined in this file is NOT part of the public API of this
          package. Users CANNOT rely on this file being available, or stored in
          this location. Nor can they rely on the existence of the macro.
  -->
    <transmission name="d_bot_shoulder_pan_trans">
        <type>transmission_interface/SimpleTransmission</type>
        <joint name="d_bot_shoulder_pan_joint">
            <hardwareInterface>hardware_interface/PositionJointInterface</hardwareInterface>
        </joint>
        <actuator name="d_bot_shoulder_pan_motor">
            <mechanicalReduction>1</mechanicalReduction>
            <hardwareInterface>hardware_interface/EffortJointInterface</hardwareInterface>
        </actuator>
    </transmission>
    <transmission name="d_bot_shoulder_lift_trans">
        <type>transmission_interface/SimpleTransmission</type>
        <joint name="d_bot_shoulder_lift_joint">
            <hardwareInterface>hardware_interface/PositionJointInterface</hardwareInterface>
        </joint>
        <actuator name="d_bot_shoulder_lift_motor">
            <mechanicalReduction>1</mechanicalReduction>
            <hardwareInterface>hardware_interface/EffortJointInterface</hardwareInterface>
        </actuator>
    </transmission>
    <transmission name="d_bot_elbow_trans">
        <type>transmission_interface/SimpleTransmission</type>
        <joint name="d_bot_elbow_joint">
            <hardwareInterface>hardware_interface/PositionJointInterface</hardwareInterface>
        </joint>
        <actuator name="d_bot_elbow_motor">
            <mechanicalReduction>1</mechanicalReduction>
            <hardwareInterface>hardware_interface/EffortJointInterface</hardwareInterface>
        </actuator>
    </transmission>
    <transmission name="d_bot_wrist_1_trans">
        <type>transmission_interface/SimpleTransmission</type>
        <joint name="d_bot_wrist_1_joint">
            <hardwareInterface>hardware_interface/PositionJointInterface</hardwareInterface>
        </joint>
        <actuator name="d_bot_wrist_1_motor">
            <mechanicalReduction>1</mechanicalReduction>
            <hardwareInterface>hardware_interface/EffortJointInterface</hardwareInterface>
        </actuator>
    </transmission>
    <transmission name="d_bot_wrist_2_trans">
        <type>transmission_interface/SimpleTransmission</type>
        <joint name="d_bot_wrist_2_joint">
            <hardwareInterface>hardware_interface/PositionJointInterface</hardwareInterface>
        </joint>
        <actuator name="d_bot_wrist_2_motor">
            <mechanicalReduction>1</mechanicalReduction>
            <hardwareInterface>hardware_interface/EffortJointInterface</hardwareInterface>
        </actuator>
    </transmission>
    <transmission name="d_bot_wrist_3_trans">
        <type>transmission_interface/SimpleTransmission</type>
        <joint name="d_bot_wrist_3_joint">
            <hardwareInterface>hardware_interface/PositionJointInterface</hardwareInterface>
        </joint>
        <actuator name="d_bot_wrist_3_motor">
            <mechanicalReduction>1</mechanicalReduction>
            <hardwareInterface>hardware_interface/EffortJointInterface</hardwareInterface>
        </actuator>
    </transmission>
    <!-- links: main serial chain -->
    <link name="d_bot_base_link" />
    <link name="d_bot_base_link_inertia">
        <visual>
            <origin rpy="0 0 3.141592653589793" xyz="0 0 0" />
            <geometry>
                <mesh filename="package://ur_description/meshes/ur5e/visual/base.dae" />
            </geometry>
            <material name="LightGrey">
                <color rgba="0.7 0.7 0.7 1.0" />
            </material>
        </visual>
        <collision>
            <origin rpy="0 0 3.141592653589793" xyz="0 0 0" />
            <geometry>
                <mesh filename="package://ur_description/meshes/ur5e/collision/base.stl" />
            </geometry>
        </collision>
        <inertial>
            <mass value="4.0" />
            <origin rpy="0 0 0" xyz="0 0 0" />
            <inertia ixx="0.00443333156" ixy="0.0" ixz="0.0" iyy="0.00443333156" iyz="0.0" izz="0.0072" />
        </inertial>
    </link>
    <link name="d_bot_shoulder_link">
        <visual>
            <origin rpy="0 0 3.141592653589793" xyz="0 0 0" />
            <geometry>
                <mesh filename="package://ur_description/meshes/ur5e/visual/shoulder.dae" />
            </geometry>
            <material name="LightGrey">
                <color rgba="0.7 0.7 0.7 1.0" />
            </material>
        </visual>
        <collision>
            <origin rpy="0 0 3.141592653589793" xyz="0 0 0" />
            <geometry>
                <mesh filename="package://ur_description/meshes/ur5e/collision/shoulder.stl" />
            </geometry>
        </collision>
        <inertial>
            <mass value="3.7" />
            <origin rpy="0 0 0" xyz="0 0 0" />
            <inertia ixx="0.010267495893" ixy="0.0" ixz="0.0" iyy="0.010267495893" iyz="0.0" izz="0.00666" />
        </inertial>
    </link>
    <link name="d_bot_upper_arm_link">
        <visual>
            <origin rpy="1.5707963267948966 0 -1.5707963267948966" xyz="0 0 0.138" />
            <geometry>
                <mesh filename="package://ur_description/meshes/ur5e/visual/upperarm.dae" />
            </geometry>
            <material name="LightGrey">
                <color rgba="0.7 0.7 0.7 1.0" />
            </material>
        </visual>
        <collision>
            <origin rpy="1.5707963267948966 0 -1.5707963267948966" xyz="0 0 0.138" />
            <geometry>
                <mesh filename="package://ur_description/meshes/ur5e/collision/upperarm.stl" />
            </geometry>
        </collision>
        <inertial>
            <mass value="8.393" />
            <origin rpy="0 1.5707963267948966 0" xyz="-0.2125 0.0 0.138" />
            <inertia ixx="0.1338857818623325" ixy="0.0" ixz="0.0" iyy="0.1338857818623325" iyz="0.0" izz="0.0151074" />
        </inertial>
    </link>
    <link name="d_bot_forearm_link">
        <visual>
            <origin rpy="1.5707963267948966 0 -1.5707963267948966" xyz="0 0 0.007" />
            <geometry>
                <mesh filename="package://ur_description/meshes/ur5e/visual/forearm.dae" />
            </geometry>
            <material name="LightGrey">
                <color rgba="0.7 0.7 0.7 1.0" />
            </material>
        </visual>
        <collision>
            <origin rpy="1.5707963267948966 0 -1.5707963267948966" xyz="0 0 0.007" />
            <geometry>
                <mesh filename="package://ur_description/meshes/ur5e/collision/forearm.stl" />
            </geometry>
        </collision>
        <inertial>
            <mass value="2.275" />
            <origin rpy="0 1.5707963267948966 0" xyz="-0.1961 0.0 0.007" />
            <inertia ixx="0.031209355099586295" ixy="0.0" ixz="0.0" iyy="0.031209355099586295" iyz="0.0" izz="0.004095" />
        </inertial>
    </link>
    <link name="d_bot_wrist_1_link">
        <visual>
            <!-- TODO: Move this to a parameter -->
            <origin rpy="1.5707963267948966 0 0" xyz="0 0 -0.127" />
            <geometry>
                <mesh filename="package://ur_description/meshes/ur5e/visual/wrist1.dae" />
            </geometry>
            <material name="LightGrey">
                <color rgba="0.7 0.7 0.7 1.0" />
            </material>
        </visual>
        <collision>
            <origin rpy="1.5707963267948966 0 0" xyz="0 0 -0.127" />
            <geometry>
                <mesh filename="package://ur_description/meshes/ur5e/collision/wrist1.stl" />
            </geometry>
        </collision>
        <inertial>
            <mass value="1.219" />
            <origin rpy="0 0 0" xyz="0 0 0" />
            <inertia ixx="0.0025598989760400002" ixy="0.0" ixz="0.0" iyy="0.0025598989760400002" iyz="0.0" izz="0.0021942" />
        </inertial>
    </link>
    <link name="d_bot_wrist_2_link">
        <visual>
            <origin rpy="0 0 0" xyz="0 0 -0.0997" />
            <geometry>
                <mesh filename="package://ur_description/meshes/ur5e/visual/wrist2.dae" />
            </geometry>
            <material name="LightGrey">
                <color rgba="0.7 0.7 0.7 1.0" />
            </material>
        </visual>
        <collision>
            <origin rpy="0 0 0" xyz="0 0 -0.0997" />
            <geometry>
                <mesh filename="package://ur_description/meshes/ur5e/collision/wrist2.stl" />
            </geometry>
        </collision>
        <inertial>
            <mass value="1.219" />
            <origin rpy="0 0 0" xyz="0 0 0" />
            <inertia ixx="0.0025598989760400002" ixy="0.0" ixz="0.0" iyy="0.0025598989760400002" iyz="0.0" izz="0.0021942" />
        </inertial>
    </link>
    <link name="d_bot_wrist_3_link">
        <visual>
            <origin rpy="1.5707963267948966 0 0" xyz="0 0 -0.0989" />
            <geometry>
                <mesh filename="package://ur_description/meshes/ur5e/visual/wrist3.dae" />
            </geometry>
            <material name="LightGrey">
                <color rgba="0.7 0.7 0.7 1.0" />
            </material>
        </visual>
        <collision>
            <origin rpy="1.5707963267948966 0 0" xyz="0 0 -0.0989" />
            <geometry>
                <mesh filename="package://ur_description/meshes/ur5e/collision/wrist3.stl" />
            </geometry>
        </collision>
        <inertial>
            <mass value="0.1879" />
            <origin rpy="0 0 0" xyz="0.0 0.0 -0.0229" />
            <inertia ixx="9.890410052167731e-05" ixy="0.0" ixz="0.0" iyy="9.890410052167731e-05" iyz="0.0" izz="0.0001321171875" />
        </inertial>
    </link>
    <!-- joints: main serial chain -->
    <joint name="d_bot_base_link-base_link_inertia" type="fixed">
        <parent link="d_bot_base_link" />
        <child link="d_bot_base_link_inertia" />
        <!-- 'base_link' is REP-103 aligned (so X+ forward), while the internal
           frames of the robot/controller have X+ pointing backwards.
           Use the joint between 'base_link' and 'base_link_inertia' (a dummy
           link/frame) to introduce the necessary rotation over Z (of pi rad).
      -->
        <origin rpy="0 0 3.141592653589793" xyz="0 0 0" />
    </joint>
    <joint name="d_bot_shoulder_pan_joint" type="revolute">
        <parent link="d_bot_base_link_inertia" />
        <child link="d_bot_shoulder_link" />
        <origin rpy="0 0 -4.860803698187189e-08" xyz="0 0 0.1625822486895494" />
        <axis xyz="0 0 1" />
        <limit effort="150.0" lower="-6.283185307179586" upper="6.283185307179586" velocity="3.141592653589793" />
        <dynamics damping="0" friction="0" />
    </joint>
    <joint name="d_bot_shoulder_lift_joint" type="revolute">
        <parent link="d_bot_shoulder_link" />
        <child link="d_bot_upper_arm_link" />
        <origin rpy="1.56951607650966 0 5.503319613557504e-06" xyz="0.0002074663022755669 0 0" />
        <axis xyz="0 0 1" />
        <limit effort="150.0" lower="-6.283185307179586" upper="6.283185307179586" velocity="3.141592653589793" />
        <dynamics damping="0" friction="0" />
    </joint>
    <joint name="d_bot_elbow_joint" type="revolute">
        <parent link="d_bot_upper_arm_link" />
        <child link="d_bot_forearm_link" />
        <origin rpy="3.140083468483962 3.139463358874167 3.141591739946795" xyz="-0.4252697394631374 0 0" />
        <axis xyz="0 0 1" />
        <limit effort="150.0" lower="-3.141592653589793" upper="3.141592653589793" velocity="3.141592653589793" />
        <dynamics damping="0" friction="0" />
    </joint>
    <joint name="d_bot_wrist_1_joint" type="revolute">
        <parent link="d_bot_forearm_link" />
        <child link="d_bot_wrist_1_link" />
        <origin rpy="0.002574948814886574 -0.001304164061105902 -6.012416228004125e-08" xyz="-0.3923973439500903 -0.0003438189965217265 0.1335242994549136" />
        <axis xyz="0 0 1" />
        <limit effort="28.0" lower="-6.283185307179586" upper="6.283185307179586" velocity="3.141592653589793" />
        <dynamics damping="0" friction="0" />
    </joint>
    <joint name="d_bot_wrist_2_joint" type="revolute">
        <parent link="d_bot_wrist_1_link" />
        <child link="d_bot_wrist_2_link" />
        <origin rpy="1.570165205517265 0 1.853249323023541e-06" xyz="-7.955210787188311e-05 -0.09952104103692579 6.280985490980155e-05" />
        <axis xyz="0 0 1" />
        <limit effort="28.0" lower="-6.283185307179586" upper="6.283185307179586" velocity="3.141592653589793" />
        <dynamics damping="0" friction="0" />
    </joint>
    <joint name="d_bot_wrist_3_joint" type="revolute">
        <parent link="d_bot_wrist_2_link" />
        <child link="d_bot_wrist_3_link" />
        <origin rpy="1.573130236699642 3.141592653589793 -3.141592597674955" xyz="0.0001681472160313707 0.09942002878844361 0.0002320378112333604" />
        <axis xyz="0 0 1" />
        <limit effort="28.0" lower="-6.283185307179586" upper="6.283185307179586" velocity="3.141592653589793" />
        <dynamics damping="0" friction="0" />
    </joint>
    <!-- ROS-Industrial 'base' frame: base_link to UR 'Base' Coordinates transform -->
    <link name="d_bot_base" />
    <joint name="d_bot_base_link-base_fixed_joint" type="fixed">
        <!-- Note the rotation over Z of pi radians: as base_link is REP-103
           aligned (ie: has X+ forward, Y+ left and Z+ up), this is needed
           to correctly align 'base' with the 'Base' coordinate system of
           the UR controller.
      -->
        <origin rpy="0 0 3.141592653589793" xyz="0 0 0" />
        <parent link="d_bot_base_link" />
        <child link="d_bot_base" />
    </joint>
    <!-- ROS-Industrial 'flange' frame: attachment point for EEF models -->
    <link name="d_bot_flange" />
    <joint name="d_bot_wrist_3-flange" type="fixed">
        <parent link="d_bot_wrist_3_link" />
        <child link="d_bot_flange" />
        <origin rpy="0 -1.5707963267948966 -1.5707963267948966" xyz="0 0 0" />
    </joint>
    <!-- ROS-Industrial 'tool0' frame: all-zeros tool frame -->
    <link name="d_bot_tool0" />
    <joint name="d_bot_flange-tool0" type="fixed">
        <!-- default toolframe: X+ left, Y+ up, Z+ front -->
        <origin rpy="1.5707963267948966 0 1.5707963267948966" xyz="0 0 0" />
        <parent link="d_bot_flange" />
        <child link="d_bot_tool0" />
    </joint>
    <!-- Configure self collision properties per link -->
    <gazebo reference="d_bot_shoulder_link">
        <selfCollide>true</selfCollide>
    </gazebo>
    <gazebo reference="d_bot_upper_arm_link">
        <selfCollide>true</selfCollide>
    </gazebo>
    <gazebo reference="d_bot_forearm_link">
        <selfCollide>true</selfCollide>
    </gazebo>
    <gazebo reference="d_bot_wrist_1_link">
        <selfCollide>true</selfCollide>
    </gazebo>
    <gazebo reference="d_bot_wrist_3_link">
        <selfCollide>true</selfCollide>
    </gazebo>
    <gazebo reference="d_bot_wrist_2_link">
        <selfCollide>true</selfCollide>
    </gazebo>
    <gazebo reference="d_bot_ee_link">
        <selfCollide>true</selfCollide>
    </gazebo>
    <!--
      Inject Gazebo ROS Control plugin, which allows us to use ros_control
      controllers to control the virtual robot hw.
    -->
    <gazebo>
        <plugin filename="libgazebo_ros_control.so" name="ros_control">
            <!--robotNamespace>/</robotNamespace-->
            <!--robotSimType>gazebo_ros_control/DefaultRobotHWSim</robotSimType-->
        </plugin>
    </gazebo>
    <joint name="ground_d_bot_joint" type="fixed">
        <parent link="ground" />
        <child link="d_bot_base_link" />
        <origin rpy="0 0 3.141592653589793" xyz="0 0.4875 0.77" />
    </joint>
    <link name="d_bot_dual_bracket_base_link">
        <inertial>
            <origin rpy="0 0 0" xyz="8.625E-08 -4.6583E-06 0.03145" />
            <mass value="0.22652" />
            <inertia ixx="0.00020005" ixy="-4.2442E-10" ixz="-2.9069E-10" iyy="0.00017832" iyz="-3.4402E-08" izz="0.00013478" />
        </inertial>
        <visual>
            <origin rpy="-1.5707963267948966 -1.5707963267948966 0" xyz="-0.0685 -0.1215 0.024" />
            <geometry>
                <mesh filename="package://aist_robotiq/meshes/visual/robotiq_dual_bracket.stl" scale="0.001 0.001 0.001" />
            </geometry>
            <material name="">
                <color rgba="0.1 0.1 0.1 1" />
            </material>
        </visual>
        <collision>
            <origin rpy="-1.5707963267948966 -1.5707963267948966 0" xyz="-0.068 -0.120 0.024" />
            <geometry>
                <mesh filename="package://aist_robotiq/meshes/collision/robotiq_dual_bracket.stl" scale="0.001 0.001 0.001" />
            </geometry>
        </collision>
    </link>
    <gazebo reference="d_bot_dual_bracket_base_link">
        <material>Gazebo/Black</material>
    </gazebo>
    <joint name="d_bot_dual_bracket_base_joint" type="fixed">
        <parent link="d_bot_flange" />
        <child link="d_bot_dual_bracket_base_link" />
        <origin rpy="3.141592653589793 0 0" xyz="0 0 0" />
    </joint>
    <link name="d_bot_dual_bracket_left_flange_link" />
    <joint name="d_bot_dual_bracket_left_flange_joint" type="fixed">
        <parent link="d_bot_dual_bracket_base_link" />
        <child link="d_bot_dual_bracket_left_flange_link" />
        <origin rpy="0 0 0.7853981633974483" xyz="0.0266 0.0427 0" />
    </joint>
    <link name="d_bot_dual_bracket_right_flange_link" />
    <joint name="d_bot_dual_bracket_right_flange_joint" type="fixed">
        <parent link="d_bot_dual_bracket_base_link" />
        <child link="d_bot_dual_bracket_right_flange_link" />
        <origin rpy="0 0 -0.7853981633974483" xyz=" 0.0266 -0.0427 0" />
    </joint>
    <link name="d_bot_left_coupling_base_link">
        <inertial>
            <origin rpy="0 0 0" xyz="8.625E-08 -4.6583E-06 0.03145" />
            <mass value="0.22652" />
            <inertia ixx="0.00020005" ixy="-4.2442E-10" ixz="-2.9069E-10" iyy="0.00017832" iyz="-3.4402E-08" izz="0.00013478" />
        </inertial>
        <visual>
            <origin rpy="1.5707963267948966 0 1.5707963267948966" xyz="0.00555 0 0" />
            <geometry>
                <mesh filename="package://aist_robotiq/meshes/visual/robotiq_arg2f_coupling.stl" scale="0.001 0.001 0.001" />
            </geometry>
            <material name="">
                <color rgba="0.1 0.1 0.1 1" />
            </material>
        </visual>
        <collision>
            <origin rpy="0 1.5707963267948966 0" xyz="0.00555 0 0" />
            <geometry>
                <cylinder length="0.0111" radius="0.0375" />
            </geometry>
        </collision>
    </link>
    <gazebo reference="d_bot_left_coupling_base_link">
        <material>Gazebo/Black</material>
    </gazebo>
    <joint name="d_bot_left_coupling_base_joint" type="fixed">
        <parent link="d_bot_dual_bracket_left_flange_link" />
        <child link="d_bot_left_coupling_base_link" />
        <origin rpy="0 0 0" xyz="0 0 0" />
    </joint>
    <link name="d_bot_left_coupling_flange_link" />
    <joint name="d_bot_left_coupling_flange_joint" type="fixed">
        <parent link="d_bot_left_coupling_base_link" />
        <child link="d_bot_left_coupling_flange_link" />
        <origin rpy="0 0 0" xyz="0.0111 0 0" />
    </joint>
    <joint name="d_bot_gripper_base_joint" type="fixed">
        <parent link="d_bot_left_coupling_flange_link" />
        <child link="d_bot_gripper_base_link" />
        <origin rpy="0 0 0" xyz="0 0 0" />
    </joint>
    <link name="d_bot_gripper_base_link" />
    <joint name="d_bot_gripper_robotiq_arg2f_base_joint" type="fixed">
        <parent link="d_bot_gripper_base_link" />
        <child link="d_bot_gripper_robotiq_arg2f_base_link" />
        <origin rpy="3.141592653589793 -1.5707963267948966 0" xyz="0 0 0" />
    </joint>
    <joint name="d_bot_gripper_tip_link_joint" type="fixed">
        <parent link="d_bot_gripper_base_link" />
        <child link="d_bot_gripper_tip_link" />
        <origin rpy="0.0 -1.5707963267948966 0.0" xyz=".2328 0.0 0.0" />
    </joint>
    <link name="d_bot_gripper_tip_link" />
    <link name="d_bot_gripper_robotiq_arg2f_base_link">
        <inertial>
            <origin rpy="0 0 0" xyz="8.625E-08 -4.6583E-06 0.03145" />
            <mass value="0.22652" />
            <inertia ixx="0.00020005" ixy="-4.2442E-10" ixz="-2.9069E-10" iyy="0.00017832" iyz="-3.4402E-08" izz="0.00013478" />
        </inertial>
        <visual>
            <origin rpy="0 0 0" xyz="0 0 0" />
            <geometry>
                <mesh filename="package://aist_robotiq/meshes/visual/robotiq_arg2f_base_link.stl" />
            </geometry>
            <material name="">
                <color rgba="0.1 0.1 0.1 1" />
            </material>
        </visual>
        <collision>
            <origin rpy="0 0 0" xyz="0 0 0" />
            <geometry>
                <mesh filename="package://aist_robotiq/meshes/collision/robotiq_arg2f_base_link.stl" />
            </geometry>
        </collision>
    </link>
    <gazebo reference="d_bot_gripper_robotiq_arg2f_base_link">
        <material>Gazebo/Black</material>
    </gazebo>
    <link name="d_bot_gripper_left_outer_knuckle">
        <inertial>
            <origin rpy="0 0 0" xyz="-0.000200000000003065        0.0199435877845359        0.0292245259211331" />
            <mass value="0.00853198276973456" />
            <inertia ixx="2.89328108496468E-06" ixy="-1.57935047237397E-19" ixz="-1.93980378593255E-19" iyy="1.86719750325683E-06" iyz="-1.21858577871576E-06" izz="1.21905238907251E-06" />
        </inertial>
        <visual>
            <origin rpy="0 0 0" xyz="0 0 0" />
            <geometry>
                <mesh filename="package://aist_robotiq/meshes/visual/robotiq_arg2f_140_outer_knuckle.stl" />
            </geometry>
            <material name="">
                <color rgba="0.792156862745098          0.819607843137255          0.933333333333333 1" />
            </material>
        </visual>
        <collision>
            <origin rpy="0 0 0" xyz="0 0 0" />
            <geometry>
                <mesh filename="package://aist_robotiq/meshes/collision/robotiq_arg2f_140_outer_knuckle.stl" />
            </geometry>
        </collision>
    </link>
    <gazebo reference="d_bot_gripper_left_outer_knuckle">
        <material>Gazebo/White</material>
    </gazebo>
    <link name="d_bot_gripper_left_outer_finger">
        <inertial>
            <origin rpy="0 0 0" xyz="0.00030115855001899        0.0373907951953854        -0.0208027427000385" />
            <mass value="0.022614240507152" />
            <inertia ixx="1.52518312458174E-05" ixy="9.76583423954399E-10" ixz="-5.43838577022588E-10" iyy="6.17694243867776E-06" iyz="6.78636130740228E-06" izz="1.16494917907219E-05" />
        </inertial>
        <visual>
            <origin rpy="0 0 0" xyz="0 0 0" />
            <geometry>
                <mesh filename="package://aist_robotiq/meshes/visual/robotiq_arg2f_140_outer_finger.stl" />
            </geometry>
            <material name="">
                <color rgba="0.1 0.1 0.1 1" />
            </material>
        </visual>
        <collision>
            <origin rpy="0 0 0" xyz="0 0 0" />
            <geometry>
                <mesh filename="package://aist_robotiq/meshes/collision/robotiq_arg2f_140_outer_finger.stl" />
            </geometry>
        </collision>
    </link>
    <gazebo reference="d_bot_gripper_left_outer_finger">
        <material>Gazebo/Black</material>
    </gazebo>
    <link name="d_bot_gripper_left_inner_finger">
        <inertial>
            <origin rpy="0 0 0" xyz="0.000299999999999317        0.0160078233491243        -0.0136945669206257" />
            <mass value="0.0104003125914103" />
            <inertia ixx="2.71909453810972E-06" ixy="1.35402465472579E-21" ixz="-7.1817349065269E-22" iyy="7.69100314106116E-07" iyz="6.74715432769696E-07" izz="2.30315190420171E-06" />
        </inertial>
        <visual>
            <origin rpy="0 0 0" xyz="0 0 0" />
            <geometry>
                <mesh filename="package://aist_robotiq/meshes/visual/robotiq_arg2f_140_inner_finger.stl" />
            </geometry>
            <material name="">
                <color rgba="0.1 0.1 0.1 1" />
            </material>
        </visual>
        <collision>
            <origin rpy="0 0 0" xyz="0 0 0" />
            <geometry>
                <mesh filename="package://aist_robotiq/meshes/collision/robotiq_arg2f_140_inner_finger.stl" />
            </geometry>
        </collision>
    </link>
    <gazebo reference="d_bot_gripper_left_inner_finger">
        <material>Gazebo/White</material>
    </gazebo>
    <link name="d_bot_gripper_left_inner_finger_pad">
        <visual>
            <origin rpy="0 0 0" xyz="0 0 0" />
            <geometry>
                <box size="0.027 0.065 0.0075" />
            </geometry>
            <material name="">
                <color rgba="0.9 0.9 0.9 1" />
            </material>
        </visual>
        <collision>
            <origin rpy="0 0 0" xyz="0 0 0" />
            <geometry>
                <box size="0.03 0.07 0.0075" />
            </geometry>
            <material name="">
                <color rgba="0.9 0.0 0.0 1" />
            </material>
        </collision>
        <inertial>
            <mass value="0.1" />
            <origin xyz="0 0 0" rpy="0 0 0" />
            <inertia ixx="0.03" iyy="0.03" izz="0.03" ixy="0.0" ixz="0.0" iyz="0.0" />
        </inertial>
    </link>
    <gazebo reference="d_bot_gripper_left_inner_finger_pad">
        <material>Gazebo/Black</material>
    </gazebo>
    <link name="d_bot_gripper_left_inner_knuckle">
        <inertial>
            <origin rpy="0 0 0" xyz="0.000123011831763771        0.0507850843201817        0.00103968640075166" />
            <mass value="0.0271177346495152" />
            <inertia ixx="2.61910379223783E-05" ixy="-2.43616858946494E-07" ixz="-6.37789906117123E-09" iyy="2.8270243746167E-06" iyz="-5.37200748039765E-07" izz="2.83695868220296E-05" />
        </inertial>
        <visual>
            <origin rpy="0 0 0" xyz="0 0 0" />
            <geometry>
                <mesh filename="package://aist_robotiq/meshes/visual/robotiq_arg2f_140_inner_knuckle.stl" />
            </geometry>
            <material name="">
                <color rgba="0.1 0.1 0.1 1" />
            </material>
        </visual>
        <collision>
            <origin rpy="0 0 0" xyz="0 0 0" />
            <geometry>
                <mesh filename="package://aist_robotiq/meshes/collision/robotiq_arg2f_140_inner_knuckle.stl" />
            </geometry>
        </collision>
    </link>
    <gazebo reference="d_bot_gripper_left_inner_knuckle">
        <material>Gazebo/Black</material>
    </gazebo>
    <link name="d_bot_gripper_right_outer_knuckle">
        <inertial>
            <origin rpy="0 0 0" xyz="-0.000200000000003065        0.0199435877845359        0.0292245259211331" />
            <mass value="0.00853198276973456" />
            <inertia ixx="2.89328108496468E-06" ixy="-1.57935047237397E-19" ixz="-1.93980378593255E-19" iyy="1.86719750325683E-06" iyz="-1.21858577871576E-06" izz="1.21905238907251E-06" />
        </inertial>
        <visual>
            <origin rpy="0 0 0" xyz="0 0 0" />
            <geometry>
                <mesh filename="package://aist_robotiq/meshes/visual/robotiq_arg2f_140_outer_knuckle.stl" />
            </geometry>
            <material name="">
                <color rgba="0.792156862745098          0.819607843137255          0.933333333333333 1" />
            </material>
        </visual>
        <collision>
            <origin rpy="0 0 0" xyz="0 0 0" />
            <geometry>
                <mesh filename="package://aist_robotiq/meshes/collision/robotiq_arg2f_140_outer_knuckle.stl" />
            </geometry>
        </collision>
    </link>
    <gazebo reference="d_bot_gripper_right_outer_knuckle">
        <material>Gazebo/White</material>
    </gazebo>
    <link name="d_bot_gripper_right_outer_finger">
        <inertial>
            <origin rpy="0 0 0" xyz="0.00030115855001899        0.0373907951953854        -0.0208027427000385" />
            <mass value="0.022614240507152" />
            <inertia ixx="1.52518312458174E-05" ixy="9.76583423954399E-10" ixz="-5.43838577022588E-10" iyy="6.17694243867776E-06" iyz="6.78636130740228E-06" izz="1.16494917907219E-05" />
        </inertial>
        <visual>
            <origin rpy="0 0 0" xyz="0 0 0" />
            <geometry>
                <mesh filename="package://aist_robotiq/meshes/visual/robotiq_arg2f_140_outer_finger.stl" />
            </geometry>
            <material name="">
                <color rgba="0.1 0.1 0.1 1" />
            </material>
        </visual>
        <collision>
            <origin rpy="0 0 0" xyz="0 0 0" />
            <geometry>
                <mesh filename="package://aist_robotiq/meshes/collision/robotiq_arg2f_140_outer_finger.stl" />
            </geometry>
        </collision>
    </link>
    <gazebo reference="d_bot_gripper_right_outer_finger">
        <material>Gazebo/Black</material>
    </gazebo>
    <link name="d_bot_gripper_right_inner_finger">
        <inertial>
            <origin rpy="0 0 0" xyz="0.000299999999999317        0.0160078233491243        -0.0136945669206257" />
            <mass value="0.0104003125914103" />
            <inertia ixx="2.71909453810972E-06" ixy="1.35402465472579E-21" ixz="-7.1817349065269E-22" iyy="7.69100314106116E-07" iyz="6.74715432769696E-07" izz="2.30315190420171E-06" />
        </inertial>
        <visual>
            <origin rpy="0 0 0" xyz="0 0 0" />
            <geometry>
                <mesh filename="package://aist_robotiq/meshes/visual/robotiq_arg2f_140_inner_finger.stl" />
            </geometry>
            <material name="">
                <color rgba="0.1 0.1 0.1 1" />
            </material>
        </visual>
        <collision>
            <origin rpy="0 0 0" xyz="0 0 0" />
            <geometry>
                <mesh filename="package://aist_robotiq/meshes/collision/robotiq_arg2f_140_inner_finger.stl" />
            </geometry>
        </collision>
    </link>
    <gazebo reference="d_bot_gripper_right_inner_finger">
        <material>Gazebo/White</material>
    </gazebo>
    <link name="d_bot_gripper_right_inner_finger_pad">
        <visual>
            <origin rpy="0 0 0" xyz="0 0 0" />
            <geometry>
                <box size="0.027 0.065 0.0075" />
            </geometry>
            <material name="">
                <color rgba="0.9 0.9 0.9 1" />
            </material>
        </visual>
        <collision>
            <origin rpy="0 0 0" xyz="0 0 0" />
            <geometry>
                <box size="0.03 0.07 0.0075" />
            </geometry>
            <material name="">
                <color rgba="0.9 0.0 0.0 1" />
            </material>
        </collision>
        <inertial>
            <mass value="0.1" />
            <origin xyz="0 0 0" rpy="0 0 0" />
            <inertia ixx="0.03" iyy="0.03" izz="0.03" ixy="0.0" ixz="0.0" iyz="0.0" />
        </inertial>
    </link>
    <gazebo reference="d_bot_gripper_right_inner_finger_pad">
        <material>Gazebo/Black</material>
    </gazebo>
    <link name="d_bot_gripper_right_inner_knuckle">
        <inertial>
            <origin rpy="0 0 0" xyz="0.000123011831763771        0.0507850843201817        0.00103968640075166" />
            <mass value="0.0271177346495152" />
            <inertia ixx="2.61910379223783E-05" ixy="-2.43616858946494E-07" ixz="-6.37789906117123E-09" iyy="2.8270243746167E-06" iyz="-5.37200748039765E-07" izz="2.83695868220296E-05" />
        </inertial>
        <visual>
            <origin rpy="0 0 0" xyz="0 0 0" />
            <geometry>
                <mesh filename="package://aist_robotiq/meshes/visual/robotiq_arg2f_140_inner_knuckle.stl" />
            </geometry>
            <material name="">
                <color rgba="0.1 0.1 0.1 1" />
            </material>
        </visual>
        <collision>
            <origin rpy="0 0 0" xyz="0 0 0" />
            <geometry>
                <mesh filename="package://aist_robotiq/meshes/collision/robotiq_arg2f_140_inner_knuckle.stl" />
            </geometry>
        </collision>
    </link>
    <gazebo reference="d_bot_gripper_right_inner_knuckle">
        <material>Gazebo/Black</material>
    </gazebo>
    <joint name="d_bot_gripper_finger_joint" type="revolute">
        <origin rpy="2.2957963267948966 0 0" xyz="0 -0.030601 0.054905" />
        <parent link="d_bot_gripper_robotiq_arg2f_base_link" />
        <child link="d_bot_gripper_left_outer_knuckle" />
        <axis xyz="-1 0 0" />
        <limit effort="1000" lower="0" upper="0.7" velocity="2.0" />
    </joint>
    <joint name="d_bot_gripper_left_outer_finger_joint" type="fixed">
        <origin rpy="0 0 0" xyz="0 0.01821998610742 0.0260018192872234" />
        <parent link="d_bot_gripper_left_outer_knuckle" />
        <child link="d_bot_gripper_left_outer_finger" />
        <axis xyz="1 0 0" />
    </joint>
    <joint name="d_bot_gripper_left_inner_knuckle_joint" type="revolute">
        <origin rpy="2.2957963267948966 0 0.0" xyz="0 -0.0127 0.06142" />
        <parent link="d_bot_gripper_robotiq_arg2f_base_link" />
        <child link="d_bot_gripper_left_inner_knuckle" />
        <axis xyz="-1 0 0" />
        <limit effort="1000" lower="-0.8757" upper="0.8757" velocity="2.0" />
        <mimic joint="d_bot_gripper_finger_joint" multiplier="1" offset="0" />
    </joint>
    <joint name="d_bot_gripper_left_inner_finger_joint" type="revolute">
        <origin rpy="-0.725 0 0" xyz="0 0.0817554015893473 -0.0282203446692936" />
        <parent link="d_bot_gripper_left_outer_finger" />
        <child link="d_bot_gripper_left_inner_finger" />
        <axis xyz="-1 0 0" />
        <limit effort="1000" lower="-0.8757" upper="0.8757" velocity="2.0" />
        <mimic joint="d_bot_gripper_finger_joint" multiplier="-1" offset="0" />
    </joint>
    <joint name="d_bot_gripper_left_inner_finger_pad_joint" type="fixed">
        <origin rpy="0 0 0" xyz="0 0.0457554015893473 -0.0272203446692936" />
        <parent link="d_bot_gripper_left_inner_finger" />
        <child link="d_bot_gripper_left_inner_finger_pad" />
        <axis xyz="0 0 1" />
    </joint>
    <joint name="d_bot_gripper_right_outer_knuckle_joint" type="revolute">
        <origin rpy="2.2957963267948966 0 3.141592653589793" xyz="0 0.030601 0.054905" />
        <parent link="d_bot_gripper_robotiq_arg2f_base_link" />
        <child link="d_bot_gripper_right_outer_knuckle" />
        <axis xyz="-1 0 0" />
        <limit effort="1000" lower="-0.725" upper="0.725" velocity="2.0" />
        <mimic joint="d_bot_gripper_finger_joint" multiplier="1" offset="0" />
    </joint>
    <joint name="d_bot_gripper_right_outer_finger_joint" type="fixed">
        <origin rpy="0 0 0" xyz="0 0.01821998610742 0.0260018192872234" />
        <parent link="d_bot_gripper_right_outer_knuckle" />
        <child link="d_bot_gripper_right_outer_finger" />
        <axis xyz="1 0 0" />
    </joint>
    <joint name="d_bot_gripper_right_inner_knuckle_joint" type="revolute">
        <origin rpy="2.2957963267948966 0 -3.141592653589793" xyz="0 0.0127 0.06142" />
        <parent link="d_bot_gripper_robotiq_arg2f_base_link" />
        <child link="d_bot_gripper_right_inner_knuckle" />
        <axis xyz="-1 0 0" />
        <limit effort="1000" lower="-0.8757" upper="0.8757" velocity="2.0" />
        <mimic joint="d_bot_gripper_finger_joint" multiplier="1" offset="0" />
    </joint>
    <joint name="d_bot_gripper_right_inner_finger_joint" type="revolute">
        <origin rpy="-0.725 0 0" xyz="0 0.0817554015893473 -0.0282203446692936" />
        <parent link="d_bot_gripper_right_outer_finger" />
        <child link="d_bot_gripper_right_inner_finger" />
        <axis xyz="-1 0 0" />
        <limit effort="1000" lower="-0.8757" upper="0.8757" velocity="2.0" />
        <mimic joint="d_bot_gripper_finger_joint" multiplier="-1" offset="0" />
    </joint>
    <joint name="d_bot_gripper_right_inner_finger_pad_joint" type="fixed">
        <origin rpy="0 0 0" xyz="0 0.0457554015893473 -0.0272203446692936" />
        <parent link="d_bot_gripper_right_inner_finger" />
        <child link="d_bot_gripper_right_inner_finger_pad" />
        <axis xyz="0 0 1" />
    </joint>
    <transmission name="d_bot_gripper_finger_joint_trans">
        <type>transmission_interface/SimpleTransmission</type>
        <joint name="d_bot_gripper_finger_joint">
            <hardwareInterface>hardware_interface/PositionJointInterface</hardwareInterface>
        </joint>
        <actuator name="d_bot_gripper_finger_joint_motor">
            <mechanicalReduction>1</mechanicalReduction>
            <hardwareInterface>hardware_interface/EffortJointInterface</hardwareInterface>
        </actuator>
    </transmission>
    <!-- Mimic joints -->
    <gazebo>
        <plugin filename="libgazebo_mimic_joint_plugin.so" name="d_bot_gripper_mimic_right_outer_knuckle_joint">
            <joint>d_bot_gripper_finger_joint</joint>
            <mimicJoint>d_bot_gripper_right_outer_knuckle_joint</mimicJoint>
        </plugin>
        <plugin filename="libgazebo_mimic_joint_plugin.so" name="d_bot_gripper_mimic_left_inner_knuckle_joint">
            <joint>d_bot_gripper_finger_joint</joint>
            <mimicJoint>d_bot_gripper_left_inner_knuckle_joint</mimicJoint>
        </plugin>
        <plugin filename="libgazebo_mimic_joint_plugin.so" name="d_bot_gripper_mimic_right_inner_knuckle_joint">
            <joint>d_bot_gripper_finger_joint</joint>
            <mimicJoint>d_bot_gripper_right_inner_knuckle_joint</mimicJoint>
        </plugin>
        <plugin filename="libgazebo_mimic_joint_plugin.so" name="d_bot_gripper_mimic_left_inner_finger_joint">
            <joint>d_bot_gripper_finger_joint</joint>
            <mimicJoint>d_bot_gripper_left_inner_finger_joint</mimicJoint>
            <multiplier>-1.0</multiplier>
            <offset>0.0</offset>
        </plugin>
        <plugin filename="libgazebo_mimic_joint_plugin.so" name="d_bot_gripper_mimic_right_inner_finger_joint">
            <joint>d_bot_gripper_finger_joint</joint>
            <mimicJoint>d_bot_gripper_right_inner_finger_joint</mimicJoint>
            <multiplier>-1.0</multiplier>
            <offset>0.0</offset>
        </plugin>
    </gazebo>
    <link name="d_bot_right_coupling_base_link">
        <inertial>
            <origin rpy="0 0 0" xyz="8.625E-08 -4.6583E-06 0.03145" />
            <mass value="0.22652" />
            <inertia ixx="0.00020005" ixy="-4.2442E-10" ixz="-2.9069E-10" iyy="0.00017832" iyz="-3.4402E-08" izz="0.00013478" />
        </inertial>
        <visual>
            <origin rpy="1.5707963267948966 0 1.5707963267948966" xyz="0.00555 0 0" />
            <geometry>
                <mesh filename="package://aist_robotiq/meshes/visual/robotiq_arg2f_coupling.stl" scale="0.001 0.001 0.001" />
            </geometry>
            <material name="">
                <color rgba="0.1 0.1 0.1 1" />
            </material>
        </visual>
        <collision>
            <origin rpy="0 1.5707963267948966 0" xyz="0.00555 0 0" />
            <geometry>
                <cylinder length="0.0111" radius="0.0375" />
            </geometry>
        </collision>
    </link>
    <gazebo reference="d_bot_right_coupling_base_link">
        <material>Gazebo/Black</material>
    </gazebo>
    <joint name="d_bot_right_coupling_base_joint" type="fixed">
        <parent link="d_bot_dual_bracket_right_flange_link" />
        <child link="d_bot_right_coupling_base_link" />
        <origin rpy="0 0 0" xyz="0 0 0" />
    </joint>
    <link name="d_bot_right_coupling_flange_link" />
    <joint name="d_bot_right_coupling_flange_joint" type="fixed">
        <parent link="d_bot_right_coupling_base_link" />
        <child link="d_bot_right_coupling_flange_link" />
        <origin rpy="0 0 0" xyz="0.0111 0 0" />
    </joint>
    <link name="d_bot_suction_base_link">
        <inertial>
            <origin rpy="0 0 0" xyz="0 0 0.0515" />
            <mass value="0.706" />
            <inertia ixx="3.084E-03" ixy="0" ixz="0" iyy="2.999E-03" iyz="0" izz="0.546E-03" />
        </inertial>
        <visual>
            <origin rpy="0 0 -1.5707963267948966" xyz="0.095 0 0" />
            <geometry>
                <mesh filename="package://aist_robotiq/meshes/visual/robotiq_epick.stl" scale="0.001 0.001 0.001" />
            </geometry>
            <material name="">
                <color rgba="0.1 0.1 0.1 1" />
            </material>
        </visual>
        <collision>
            <origin rpy="0 0 -1.5707963267948966" xyz="0.095 0 0" />
            <geometry>
                <mesh filename="package://aist_robotiq/meshes/collision/robotiq_epick.stl" scale="0.001 0.001 0.001" />
            </geometry>
        </collision>
    </link>
    <gazebo reference="d_bot_suction_base_link">
        <material>Gazebo/Black</material>
    </gazebo>
    <!-- Add the force sensor in front of the gripper. -->
    <joint name="d_bot_suction_base_joint" type="fixed">
        <parent link="d_bot_right_coupling_flange_link" />
        <child link="d_bot_suction_base_link" />
        <origin rpy="0 0 0" xyz="0 0 0" />
    </joint>
    <link name="d_bot_suction_flange_link" />
    <joint name="d_bot_suction_flange_joint" type="fixed">
        <parent link="d_bot_suction_base_link" />
        <child link="d_bot_suction_flange_link" />
        <origin rpy="0 0 0" xyz="0.101 0 0" />
    </joint>
    <joint name="d_phoxi_m_camera_link_joint" type="fixed">
        <parent link="workspace_center" />
        <child link="d_phoxi_m_camera_link" />
        <origin rpy="-2.6579086976420028    -0.034961612018082774    0.0" xyz="-0.0149511700982    -0.483543436025    0.633792706454" />
    </joint>
    <joint name="d_phoxi_m_camera_reference_joint" type="fixed">
        <parent link="d_phoxi_m_camera_link" />
        <child link="d_phoxi_m_camera_reference" />
        <origin rpy="0 0 0.20507618710933373" xyz="0.002164826095 -0.176277236938477 0.0299" />
    </joint>
    <link name="d_phoxi_m_camera_link">
        <visual>
            <!-- <origin xyz="0 0 0" rpy="0 1.5707 0" /> -->
            <origin rpy="0 0 0" xyz="0 0 0" />
            <geometry>
                <mesh filename="package://aist_phoxi_camera/meshes/visual/PhoXi_M.f.STL" scale="0.001 0.001 0.001" />
            </geometry>
            <material name="">
                <color rgba="0.8 0.8 0.8 1" />
            </material>
        </visual>
        <collision>
            <!-- <origin xyz="0 0 0" rpy="0 1.5707 0" /> -->
            <origin rpy="0 0 0" xyz="0 0 0" />
            <geometry>
                <mesh filename="package://aist_phoxi_camera/meshes/collision/PhoXi_M.c.STL" scale="0.001 0.001 0.001" />
            </geometry>
        </collision>
        <inertial>
            <mass value="0.1" />
            <origin xyz="0 0 0" rpy="0 0 0" />
            <inertia ixx="0.03" iyy="0.03" izz="0.03" ixy="0.0" ixz="0.0" iyz="0.0" />
        </inertial>
    </link>
    <link name="d_phoxi_m_camera_reference" />
    <link name="d_phoxi_m_camera_sensor" />
    <joint name="d_phoxi_m_camera_sensor_joint" type="fixed">
        <parent link="d_phoxi_m_camera_reference" />
        <child link="d_phoxi_m_camera_sensor" />
        <origin rpy="-1.5707963267948966 0 -1.5707963267948966" xyz="0 0 0" />
    </joint>
    <gazebo reference="d_phoxi_m_camera_reference">
        <sensor name="d_phoxi_m_camera" type="depth">
            <always_on>true</always_on>
            <visualize>true</visualize>
            <camera>
                <image>
                    <width>2064</width>
                    <height>1544</height>
                    <format>L8</format>
                </image>
                <horizontal_fov>0.9077</horizontal_fov>
                <depth_camera />
                <clip>
                    <near>0.1</near>
                    <far>100</far>
                </clip>
            </camera>
            <plugin filename="libgazebo_ros_openni_kinect.so" name="d_phoxi_m_camera_controller">
                <baseline>0.35</baseline>
                <alwaysOn>true</alwaysOn>
                <updateRate>2.5</updateRate>
                <cameraName>d_phoxi_m_camera</cameraName>
                <frameName>d_phoxi_m_camera_sensor</frameName>
                <imageTopicName>texture</imageTopicName>
                <depthImageTopicName>depth_map</depthImageTopicName>
                <pointCloudTopicName>pointcloud</pointCloudTopicName>
                <cameraInfoTopicName>camera_info</cameraInfoTopicName>
                <depthImageCameraInfoTopicName>camera_info</depthImageCameraInfoTopicName>
                <pointCloudCutoff>0.4</pointCloudCutoff>
                <!-- <hackBaseline>0.35</hackBaseline> -->
                <distortionK1>0.0</distortionK1>
                <distortionK2>0.0</distortionK2>
                <distortionK3>0.0</distortionK3>
                <distortionT1>0.0</distortionT1>
                <distortionT2>0.0</distortionT2>
                <CxPrime>0.0</CxPrime>
                <Cx>0.0</Cx>
                <Cy>0.0</Cy>
                <focalLength>0.0</focalLength>
            </plugin>
        </sensor>
    </gazebo>
    <!-- Left sensor (looking from front):  -7.54 mm, 0, -3.721 mm -->
    <!-- Right sensor (RGB?)(looking from front): 16.492 mm, 0, -3.721 mm -->
    <!-- 24.033 mm distance between the camera centers, apparently -->
    <!-- camera mount to origin: 4mm; cameras to origin: 3.721 mm. = 7.721 mm offset? -->
    <!-- I forgot which conventions exist for "camera_joint" and "camera_link_joint" so I hesitate to delete one. -->
    <joint name="d_bot_camera_joint" type="fixed">
        <origin rpy="0 0.0 0" xyz="0.030 0.000 0.043" />
        <parent link="d_bot_gripper_base_link" />
        <child link="d_bot_camera_connector_link" />
    </joint>
    <link name="d_bot_camera_connector_link" />
    <joint name="d_bot_camera_link_joint" type="fixed">
        <origin rpy="0 0 0" xyz="0 0 0" />
        <parent link="d_bot_camera_connector_link" />
        <child link="d_bot_camera_link" />
    </joint>
    <link name="d_bot_camera_link">
        <visual>
            <origin rpy="1.5707963267948966 0 1.5707963267948966" xyz="0 -0.0 0" />
            <geometry>
                <mesh filename="package://realsense2_description/meshes/sr305_without_mount.stl" scale=".001 .001 .001" />
            </geometry>
            <material name="sr305_aluminum">
                <color rgba="0.5 0.5 0.5 1" />
            </material>
        </visual>
        <collision>
            <origin rpy="0 0 0" xyz="0.006 -0.0 0" />
            <geometry>
                <box size="0.012 0.14 0.023" />
            </geometry>
        </collision>
        <inertial>
            <!-- The following are not reliable values, and should not be used for modeling -->
            <mass value="0.564" />
            <origin xyz="0 0 0" rpy="0 0 0" />
            <inertia ixx="0.003881243" ixy="0.0" ixz="0.0" iyy="0.000498940" iyz="0.0" izz="0.003879257" />
        </inertial>
    </link>
    <!-- camera depth joints and links -->
    <joint name="d_bot_camera_depth_joint" type="fixed">
        <origin rpy="0 0 0" xyz=".003721 0 0" />
        <parent link="d_bot_camera_link" />
        <child link="d_bot_camera_depth_frame" />
    </joint>
    <link name="d_bot_camera_depth_frame" />
    <joint name="d_bot_camera_depth_optical_joint" type="fixed">
        <origin rpy="-1.5707963267948966 0 -1.5707963267948966" xyz="0 0 0" />
        <parent link="d_bot_camera_depth_frame" />
        <child link="d_bot_camera_depth_optical_frame" />
    </joint>
    <link name="d_bot_camera_depth_optical_frame" />
    <!-- camera left IR joints and links -->
    <joint name="d_bot_camera_left_ir_joint" type="fixed">
        <origin rpy="0 0 0" xyz="0 0.0 0" />
        <parent link="d_bot_camera_depth_frame" />
        <child link="d_bot_camera_left_ir_frame" />
    </joint>
    <link name="d_bot_camera_left_ir_frame" />
    <joint name="d_bot_camera_left_ir_optical_joint" type="fixed">
        <origin rpy="-1.5707963267948966 0 -1.5707963267948966" xyz="0 0 0" />
        <parent link="d_bot_camera_left_ir_frame" />
        <child link="d_bot_camera_left_ir_optical_frame" />
    </joint>
    <link name="d_bot_camera_left_ir_optical_frame" />
    <!-- camera right IR joints and links -->
    <joint name="d_bot_camera_right_ir_joint" type="fixed">
        <origin rpy="0 0 0" xyz="0 0.04 0" />
        <parent link="d_bot_camera_depth_frame" />
        <child link="d_bot_camera_right_ir_frame" />
    </joint>
    <link name="d_bot_camera_right_ir_frame" />
    <joint name="d_bot_camera_right_ir_optical_joint" type="fixed">
        <origin rpy="-1.5707963267948966 0 -1.5707963267948966" xyz="0 0 0" />
        <parent link="d_bot_camera_right_ir_frame" />
        <child link="d_bot_camera_right_ir_optical_frame" />
    </joint>
    <link name="d_bot_camera_right_ir_optical_frame" />
    <!-- camera color joints and links -->
    <joint name="d_bot_camera_color_joint" type="fixed">
        <origin rpy="0 0 0" xyz="0 0.015 0" />
        <parent link="d_bot_camera_depth_frame" />
        <child link="d_bot_camera_color_frame" />
    </joint>
    <link name="d_bot_camera_color_frame" />
    <joint name="d_bot_camera_color_optical_joint" type="fixed">
        <origin rpy="-1.5707963267948966 0 -1.5707963267948966" xyz="0 0 0" />
        <parent link="d_bot_camera_color_frame" />
        <child link="d_bot_camera_color_optical_frame" />
    </joint>
    <link name="d_bot_camera_color_optical_frame" />
    <!-- Reference should be color_frame because depth is alighed to color -->
    <gazebo reference="d_bot_camera_color_frame">
        <sensor name="d_bot_camera" type="depth">
            <always_on>true</always_on>
            <visualize>true</visualize>
            <camera>
                <!-- Color sensor's FOV(VGA): 68 deg. -->
                <horizontal_fov>1.1868</horizontal_fov>
                <image>
                    <!-- VGA -->
                    <width>640</width>
                    <height>480</height>
                    <format>R8G8B8</format>
                </image>
                <depth_camera />
                <clip>
                    <near>0.1</near>
                    <far>100</far>
                </clip>
            </camera>
            <plugin filename="libgazebo_ros_openni_kinect.so" name="d_bot_camera_controller">
                <baseline>0.048</baseline>
                <alwaysOn>true</alwaysOn>
                <updateRate>10.0</updateRate>
                <cameraName>d_bot_camera</cameraName>
                <frameName>d_bot_camera_color_optical_frame</frameName>
                <imageTopicName>color/image_raw</imageTopicName>
                <cameraInfoTopicName>color/camera_info</cameraInfoTopicName>
                <depthImageTopicName>aligned_depth_to_color/image_raw</depthImageTopicName>
                <depthImageCameraInfoTopicName>aligned_depth_to_color/camera_info</depthImageCameraInfoTopicName>
                <pointCloudTopicName>depth/color/points</pointCloudTopicName>
                <pointCloudCutoff>0.1</pointCloudCutoff>
                <!-- <hackBaseline>0.07</hackBaseline> -->
                <distortionK1>0.0</distortionK1>
                <distortionK2>0.0</distortionK2>
                <distortionK3>0.0</distortionK3>
                <distortionT1>0.0</distortionT1>
                <distortionT2>0.0</distortionT2>
                <CxPrime>0.0</CxPrime>
                <Cx>0.0</Cx>
                <Cy>0.0</Cy>
                <focalLength>0.0</focalLength>
            </plugin>
        </sensor>
    </gazebo>
    <!-- I would like to remove the "world" link definition, but apparently it is necessary for Gazebo -->
    <link name="world" />
    <joint name="world_ground_joint" type="fixed">
        <parent link="world" />
        <child link="ground" />
        <origin rpy="0 0 0" xyz="0 0 0" />
    </joint>
    <transmission name="trans_d_bot_gripper_left_inner_knuckle_joint">
        <type>transmission_interface/SimpleTransmission</type>
        <joint name="d_bot_gripper_left_inner_knuckle_joint">
            <hardwareInterface>hardware_interface/EffortJointInterface</hardwareInterface>
        </joint>
        <actuator name="d_bot_gripper_left_inner_knuckle_joint_motor">
            <hardwareInterface>hardware_interface/EffortJointInterface</hardwareInterface>
            <mechanicalReduction>1</mechanicalReduction>
        </actuator>
    </transmission>
    <transmission name="trans_d_bot_gripper_left_inner_finger_joint">
        <type>transmission_interface/SimpleTransmission</type>
        <joint name="d_bot_gripper_left_inner_finger_joint">
            <hardwareInterface>hardware_interface/EffortJointInterface</hardwareInterface>
        </joint>
        <actuator name="d_bot_gripper_left_inner_finger_joint_motor">
            <hardwareInterface>hardware_interface/EffortJointInterface</hardwareInterface>
            <mechanicalReduction>1</mechanicalReduction>
        </actuator>
    </transmission>
    <transmission name="trans_d_bot_gripper_right_outer_knuckle_joint">
        <type>transmission_interface/SimpleTransmission</type>
        <joint name="d_bot_gripper_right_outer_knuckle_joint">
            <hardwareInterface>hardware_interface/EffortJointInterface</hardwareInterface>
        </joint>
        <actuator name="d_bot_gripper_right_outer_knuckle_joint_motor">
            <hardwareInterface>hardware_interface/EffortJointInterface</hardwareInterface>
            <mechanicalReduction>1</mechanicalReduction>
        </actuator>
    </transmission>
    <transmission name="trans_d_bot_gripper_right_inner_knuckle_joint">
        <type>transmission_interface/SimpleTransmission</type>
        <joint name="d_bot_gripper_right_inner_knuckle_joint">
            <hardwareInterface>hardware_interface/EffortJointInterface</hardwareInterface>
        </joint>
        <actuator name="d_bot_gripper_right_inner_knuckle_joint_motor">
            <hardwareInterface>hardware_interface/EffortJointInterface</hardwareInterface>
            <mechanicalReduction>1</mechanicalReduction>
        </actuator>
    </transmission>
    <transmission name="trans_d_bot_gripper_right_inner_finger_joint">
        <type>transmission_interface/SimpleTransmission</type>
        <joint name="d_bot_gripper_right_inner_finger_joint">
            <hardwareInterface>hardware_interface/EffortJointInterface</hardwareInterface>
        </joint>
        <actuator name="d_bot_gripper_right_inner_finger_joint_motor">
            <hardwareInterface>hardware_interface/EffortJointInterface</hardwareInterface>
            <mechanicalReduction>1</mechanicalReduction>
        </actuator>
    </transmission>
</robot>

