<?xml version="1.0"?>
<robot xmlns:xacro="http://ros.org/wiki/xacro">

  <xacro:macro name="base_fixture" params="prefix parent *origin">

    <xacro:macro name="load_properties" params="filename">
      <xacro:property name="properties"
		      value="${xacro.load_yaml(filename)['base_fixture']}"/>
      <xacro:property name="visual_meshes"
		      value="${properties['visual_meshes']}"
		      scope="parent"/>
      <xacro:property name="primitives"
		      value="${properties['primitives']}"
		      scope="parent"/>
      <xacro:property name="subframes"
		      value="${properties['subframes']}"
		      scope="parent"/>
    </xacro:macro>

    <xacro:include filename="$(find aist_fastening_tools
			     )/urdf/base_fixture_transmission.xacro"/>
    <xacro:base_fixture_transmission prefix="${prefix}"/>
    <xacro:load_properties filename="$(find aist_fastening_tools
				     )/config/fastening_tools_properties.yaml"/>

    <xacro:property name="stroke"	value="0.020"/>

    <!-- Body -->
    <xacro:property name="body_vorigin"	value="${visual_meshes[0]['pose']}"/>
    <xacro:property name="body_vscale"	value="${visual_meshes[0]['scale']}"/>
    <xacro:property name="body_vcolor"	value="${visual_meshes[0]['color']}"/>
    <xacro:property name="body_corigin" value="${primitives[0]['pose']}"/>
    <xacro:property name="body_cdims"   value="${primitives[0]['dimensions']}"/>

    <joint name="${prefix}base_joint" type="fixed">
      <parent link="${parent}"/>
      <child  link="${prefix}base_link"/>
      <xacro:insert_block name="origin"/>
    </joint>
    <link name="${prefix}base_link">
      <visual>
	<origin xyz="${body_vorigin[0]}
		     ${body_vorigin[1]}
		     ${body_vorigin[2]}"
		rpy="${body_vorigin[3]*pi/180.0}
		     ${body_vorigin[4]*pi/180.0}
		     ${body_vorigin[5]*pi/180.0}"/>
        <geometry>
          <mesh filename="${visual_meshes[0]['url']}"
		scale="${body_vscale[0]} ${body_vscale[1]} ${body_vscale[2]}"/>
        </geometry>
        <material name="Gazebo/Black">
          <color rgba="${body_vcolor[0]} ${body_vcolor[1]}
		       ${body_vcolor[2]} ${body_vcolor[3]}"/>
        </material>
      </visual>
      <collision>
	<origin xyz="${body_corigin[0]}
		     ${body_corigin[1]}
		     ${body_corigin[2]}"
		rpy="${body_corigin[3]*pi/180.0}
		     ${body_corigin[4]*pi/180.0}
		     ${body_corigin[5]*pi/180.0}"/>
        <geometry>
	  <box size="${body_cdims[0]} ${body_cdims[1]} ${body_cdims[2]}"/>
        </geometry>
      </collision>
      <inertial>
        <origin xyz="0 0 0" rpy="0 0 0"/>
        <mass value="0.86387"/>
        <inertia ixx="1017560E-9" ixy="0" ixz="2235E-9"
		 iyy="1028041E-9" iyz="0" izz="489810E-9"/>
      </inertial>
    </link>

    <!-- Piston -->
    <xacro:property name="piston_vorigin"
    		    value="${visual_meshes[1]['pose']}"/>
    <xacro:property name="piston_vscale"
    		    value="${visual_meshes[1]['scale']}"/>
    <xacro:property name="piston_vcolor"
    		    value="${visual_meshes[1]['color']}"/>
    <xacro:property name="piston_corigin"
		    value="${primitives[1]['pose']}"/>
    <xacro:property name="piston_cdims"
		    value="${primitives[1]['dimensions']}"/>

    <joint name="${prefix}piston_joint" type="prismatic">
      <parent link="${prefix}base_link"/>
      <child link="${prefix}piston"/>
      <axis xyz="1 0 0"/>
      <limit effort="130" lower="0" upper="${stroke}" velocity="0.15"/>
    </joint>
    <link name="${prefix}piston">
      <visual>
      	<origin xyz="${piston_vorigin[0]}
      		     ${piston_vorigin[1]}
      		     ${piston_vorigin[2]}"
      		rpy="${piston_vorigin[3]*pi/180.0}
      		     ${piston_vorigin[4]*pi/180.0}
      		     ${piston_vorigin[5]*pi/180.0}"/>
        <geometry>
          <mesh filename="${visual_meshes[1]['url']}"
      		scale="${piston_vscale[0]}
		       ${piston_vscale[1]}
		       ${piston_vscale[2]}"/>
        </geometry>
        <material name="Gazebo/Grey">
          <color rgba="${piston_vcolor[0]} ${piston_vcolor[1]}
      		       ${piston_vcolor[2]} ${piston_vcolor[3]}"/>
        </material>
      </visual>
      <collision>
	<origin xyz="${piston_corigin[0]}
		     ${piston_corigin[1]}
		     ${piston_corigin[2]}"
		rpy="${piston_corigin[3]*pi/180.0}
		     ${piston_corigin[4]*pi/180.0}
		     ${piston_corigin[5]*pi/180.0}"/>
        <geometry>
	  <box size="${piston_cdims[0]}
		     ${piston_cdims[1]}
		     ${piston_cdims[2]}"/>
        </geometry>
      </collision>
      <inertial>
        <origin xyz="0.02262 -0.00759 0.00738" rpy="0 0 0"/>
        <mass value="0.03804"/>
        <inertia ixx="13567E-9" ixy="1849E-9" ixz="3622E-9"
		 iyy="15784E-9" iyz="3616E-9" izz="7478E-9"/>
      </inertial>
    </link>

    <!-- Tip -->
    <xacro:property name="tip_link_origin"
		    value="${subframes['tip_link']}"/>
    <joint name="${prefix}tip_link_joint" type="fixed">
      <parent link="${prefix}base_link"/>
      <child  link="${prefix}tip_link"/>
      <origin xyz="${tip_link_origin[0]}
		   ${tip_link_origin[1]}
		   ${tip_link_origin[2]}"
	      rpy="${tip_link_origin[3]*pi/180.0}
		   ${tip_link_origin[4]*pi/180.0}
		   ${tip_link_origin[5]*pi/180.0}"/>
    </joint>
    <link name="${prefix}tip_link"/>

    <!-- Piston head -->
    <xacro:property name="piston_head_origin"
		    value="${subframes['piston_head']}"/>
    <joint name="${prefix}piston_head_joint" type="fixed">
      <parent link="${prefix}piston"/>
      <child  link="${prefix}piston_head"/>
      <origin xyz="${piston_head_origin[0]}
		   ${piston_head_origin[1]}
		   ${piston_head_origin[2]}"
	      rpy="${piston_head_origin[3]*pi/180.0}
		   ${piston_head_origin[4]*pi/180.0}
		   ${piston_head_origin[5]*pi/180.0}"/>
    </joint>
    <link name="${prefix}piston_head"/>

    <gazebo reference="${prefix}base_link">
      <material>Gazebo/FlatBlack</material>
    </gazebo>
    <gazebo reference="${prefix}piston">
      <material>Gazebo/Grey</material>
    </gazebo>

    <!-- Improve grasping physics -->
    <gazebo reference="${prefix}piston">
      <kp>1000000.0</kp>
      <kd>1.0</kd>
      <mu1>1.0</mu1>
      <mu2>1.0</mu2>
      <minDepth>0.001</minDepth>
    </gazebo>

  </xacro:macro>
</robot>
