<?xml version="1.0" ?>
<!-- =================================================================================== -->
<!-- |    This document was autogenerated by xacro from /home/artuser/catkin_ws/src/artros/aist_description/scenes/urdf/dtorobo_base_scene.urdf.xacro | -->
<!-- |    EDITING THIS FILE BY HAND IS NOT RECOMMENDED                                 | -->
<!-- =================================================================================== -->
<robot name="dtorobo_base_scene">
    <!-- Main workspace -->
    <!-- The surface is 0.01 m below the robot bases and the "workspace_center" frame. -->
    <link name="ground" />
    <!-- This creates a box with the origin in the bottom corner, fixed to the world link. -->
    <link name="workbox">
        <!-- w is in x, l is in y, h is in z -->
        <visual>
            <origin rpy="0 0 0" xyz="0.45 0.375 0.005" />
            <geometry>
                <box size="0.9 0.75 0.01" />
            </geometry>
            <material name="Grey">
                <color rgba="0.7 0.7 0.7 1" />
            </material>
        </visual>
        <collision>
            <origin rpy="0 0 0" xyz="0.45 0.375 0.005" />
            <geometry>
                <box size="0.9 0.75 0.01" />
            </geometry>
        </collision>
        <!-- This is required for Gazebo. -->
        <inertial>
            <mass value="1.0" />
            <!-- <origin xyz="${width/2} ${length} ${height/2}" rpy="0 0 0"/> -->
            <inertia ixx="0.0" ixy="0.0" ixz="0.0" iyy="0.0" iyz="0.0" izz="0.0" />
            <origin xyz="0 0 0" rpy="0 0 0" />
        </inertial>
    </link>
    <gazebo reference="workbox">
        <material>Gazebo/Grey</material>
        <plugin name="gazebo_ros_control">
            <robotNamespace>/</robotNamespace>
        </plugin>
    </gazebo>
    <joint name="workbox" type="fixed">
        <parent link="ground" />
        <child link="workbox" />
        <origin rpy="0 0 0" xyz="-0.45 -0.375 0.775" />
    </joint>
    <link name="workspace_center" />
    <joint name="ground_to_workspace" type="fixed">
        <parent link="ground" />
        <child link="workspace_center" />
        <origin rpy="0 0 0" xyz="0 0 0.785" />
    </joint>
    <!-- ros_control plugin -->
    <gazebo>
        <plugin filename="libtorobo_gazebo_ros_control.so" name="torobo_gazebo_ros_control">
            <robotNamespace>/torobo</robotNamespace>
            <robotSimType>torobo_gazebo_ros_control/DefaultRobotHWSim</robotSimType>
            <legacyModeNS>false</legacyModeNS>
        </plugin>
    </gazebo>
    <joint name="a_torobo_arm/root" type="fixed">
        <origin rpy="0 0 1.5707963267948966" xyz="0 -0.4875 0.785" />
        <parent link="ground" />
        <child link="a_torobo_arm/link_0" />
    </joint>
    <link name="a_torobo_arm/link_0">
        <visual>
            <geometry>
                <mesh filename="package://torobo_resources/meshes/arm/TRBA-R-002-7/link0.dae" scale="0.01 0.01 0.01" />
            </geometry>
            <origin xyz="0 0 0" />
        </visual>
        <collision>
            <geometry>
                <mesh filename="package://torobo_resources/meshes/arm/TRBA-R-002-7/link0.dae" scale="0.012 0.012 0.012" />
            </geometry>
            <origin xyz="0 0 0" />
        </collision>
        <inertial>
            <origin xyz="-0.000436 0.000019 0.041708" rpy="0 0 0" />
            <mass value="2.545036" />
            <inertia ixx="6.331898e-3" ixy="2.399900e-6" ixz="-3.132040e-5" iyy="6.434612e-3" iyz="1.515900e-6" izz="8.449834e-3" />
        </inertial>
    </link>
    <joint name="a_torobo_arm/joint_1" type="revolute">
        <parent link="a_torobo_arm/link_0" />
        <child link="a_torobo_arm/link_1" />
        <origin rpy="0 0 0" xyz="0 0 0.220" />
        <axis xyz="0 0 1" />
        <limit effort="110" lower="-2.9670597283903604" upper="2.9670597283903604" velocity="1.7453292519943295" />
    </joint>
    <link name="a_torobo_arm/link_1">
        <visual>
            <geometry>
                <mesh filename="package://torobo_resources/meshes/arm/TRBA-R-002-7/link1.dae" scale="0.01 0.01 0.01" />
            </geometry>
        </visual>
        <collision>
            <geometry>
                <mesh filename="package://torobo_resources/meshes/arm/TRBA-R-002-7/link1.dae" scale="0.012 0.012 0.012" />
            </geometry>
        </collision>
        <inertial>
            <origin xyz="0.000009 0.004526 -0.062965" rpy="0 0 0" />
            <mass value="4.553552" />
            <inertia ixx="2.644887e-2" ixy="5.349000e-7" ixz="4.084800e-6" iyy="2.675988e-2" iyz="-8.294709e-4" izz="7.305179e-3" />
        </inertial>
    </link>
    <joint name="a_torobo_arm/joint_2" type="revolute">
        <parent link="a_torobo_arm/link_1" />
        <child link="a_torobo_arm/link_2" />
        <origin rpy="-1.5707963267948966 0 0" xyz="0 0 0" />
        <axis xyz="0 0 1" />
        <limit effort="110" lower="-1.9198621771937625" upper="1.9198621771937625" velocity="1.7453292519943295" />
    </joint>
    <link name="a_torobo_arm/link_2">
        <visual>
            <geometry>
                <mesh filename="package://torobo_resources/meshes/arm/TRBA-R-002-7/link2.dae" scale="0.01 0.01 0.01" />
            </geometry>
        </visual>
        <collision>
            <geometry>
                <mesh filename="package://torobo_resources/meshes/arm/TRBA-R-002-7/link2.dae" scale="0.012 0.012 0.012" />
            </geometry>
        </collision>
        <inertial>
            <origin xyz="0.000000 -0.064474 -0.016924" rpy="0 0 0" />
            <mass value="2.474676" />
            <inertia ixx="1.163631e-2" ixy="-6.892000e-7" ixz="2.103000e-7" iyy="4.853435e-3" iyz="2.196366e-3" izz="1.202305e-2" />
        </inertial>
    </link>
    <joint name="a_torobo_arm/joint_3" type="revolute">
        <parent link="a_torobo_arm/link_2" />
        <child link="a_torobo_arm/link_3" />
        <origin rpy="1.5707963267948966 0 0" xyz="0 -0.3 0" />
        <axis xyz="0 0 1" />
        <limit effort="70" lower="-2.8797932657906435" upper="2.8797932657906435" velocity="2.0943951023931953" />
    </joint>
    <link name="a_torobo_arm/link_3">
        <visual>
            <geometry>
                <mesh filename="package://torobo_resources/meshes/arm/TRBA-R-002-7/link3.dae" scale="0.01 0.01 0.01" />
            </geometry>
        </visual>
        <collision>
            <geometry>
                <mesh filename="package://torobo_resources/meshes/arm/TRBA-R-002-7/link3.dae" scale="0.012 0.012 0.012" />
            </geometry>
        </collision>
        <inertial>
            <origin xyz="0.000012 0.005769 -0.066866" rpy="0 0 0" />
            <mass value="3.237919" />
            <inertia ixx="1.911238e-2" ixy="2.978000e-7" ixz="-4.962600e-6" iyy="1.915428e-2" iyz="-7.716287e-4" izz="3.920768e-3" />
        </inertial>
    </link>
    <joint name="a_torobo_arm/joint_4" type="revolute">
        <parent link="a_torobo_arm/link_3" />
        <child link="a_torobo_arm/link_4" />
        <origin rpy="-1.5707963267948966 0 0" xyz="0 0 0" />
        <axis xyz="0 0 1" />
        <limit effort="70" lower="-2.1816615649929116" upper="2.1816615649929116" velocity="2.0943951023931953" />
    </joint>
    <link name="a_torobo_arm/link_4">
        <visual>
            <geometry>
                <mesh filename="package://torobo_resources/meshes/arm/TRBA-R-002-7/link4.dae" scale="0.01 0.01 0.01" />
            </geometry>
        </visual>
        <collision>
            <geometry>
                <mesh filename="package://torobo_resources/meshes/arm/TRBA-R-002-7/link4.dae" scale="0.012 0.012 0.012" />
            </geometry>
        </collision>
        <inertial>
            <origin xyz="0.000006 -0.062765 -0.018379" rpy="0 0 0" />
            <mass value="1.945562" />
            <inertia ixx="9.626170e-3" ixy="-1.551000e-7" ixz="1.278000e-7" iyy="2.996661e-3" iyz="1.733720e-3" izz="9.870906e-3" />
        </inertial>
    </link>
    <joint name="a_torobo_arm/joint_5" type="revolute">
        <parent link="a_torobo_arm/link_4" />
        <child link="a_torobo_arm/link_5" />
        <origin rpy="1.5707963267948966 0 0" xyz="0 -0.3 0" />
        <axis xyz="0 0 1" />
        <limit effort="30" lower="-2.8797932657906435" upper="2.8797932657906435" velocity="2.792526803190927" />
    </joint>
    <link name="a_torobo_arm/link_5">
        <visual>
            <geometry>
                <mesh filename="package://torobo_resources/meshes/arm/TRBA-R-002-7/link5.dae" scale="0.01 0.01 0.01" />
            </geometry>
        </visual>
        <collision>
            <geometry>
                <mesh filename="package://torobo_resources/meshes/arm/TRBA-R-002-7/link5.dae" scale="0.012 0.012 0.012" />
            </geometry>
        </collision>
        <inertial>
            <origin xyz="-0.000009 0.010041 -0.094026" rpy="0 0 0" />
            <mass value="1.798056" />
            <inertia ixx="9.196412e-3" ixy="2.212000e-7" ixz="6.890000e-7" iyy="9.130626e-3" iyz="-1.559966e-3" izz="1.957429e-3" />
        </inertial>
    </link>
    <joint name="a_torobo_arm/joint_6" type="revolute">
        <parent link="a_torobo_arm/link_5" />
        <child link="a_torobo_arm/link_6" />
        <origin rpy="-1.5707963267948966 0 0" xyz="0 0 0" />
        <axis xyz="0 0 1" />
        <limit effort="30" lower="-2.0943951023931953" upper="2.0943951023931953" velocity="2.792526803190927" />
    </joint>
    <link name="a_torobo_arm/link_6">
        <visual>
            <geometry>
                <mesh filename="package://torobo_resources/meshes/arm/TRBA-R-002-7/link6.dae" scale="0.01 0.01 0.01" />
            </geometry>
        </visual>
        <collision>
            <geometry>
                <mesh filename="package://torobo_resources/meshes/arm/TRBA-R-002-7/link6.dae" scale="0.012 0.012 0.012" />
            </geometry>
        </collision>
        <inertial>
            <origin xyz="0.000002 -0.050748 -0.002319" rpy="0 0 0" />
            <mass value="2.271792" />
            <inertia ixx="8.528173e-3" ixy="-5.321000e-7" ixz="4.298000e-7" iyy="2.242304e-3" iyz="1.159234e-4" izz="8.444133e-3" />
        </inertial>
    </link>
    <joint name="a_torobo_arm/joint_7" type="revolute">
        <parent link="a_torobo_arm/link_6" />
        <child link="a_torobo_arm/link_7" />
        <origin rpy="1.5707963267948966 0 0" xyz="0 -0.170 0" />
        <axis xyz="0 0 1" />
        <limit effort="15" lower="-2.9670597283903604" upper="2.9670597283903604" velocity="4.1887902047863905" />
    </joint>
    <link name="a_torobo_arm/link_7">
        <visual>
            <geometry>
                <mesh filename="package://torobo_resources/meshes/arm/TRBA-R-002-7/link7.dae" scale="0.01 0.01 0.01" />
            </geometry>
        </visual>
        <collision>
            <geometry>
                <mesh filename="package://torobo_resources/meshes/arm/TRBA-R-002-7/link7.dae" scale="0.012 0.012 0.012" />
            </geometry>
        </collision>
        <inertial>
            <origin xyz="-0.000973 0.000022 -0.017659" rpy="0 0 0" />
            <mass value="0.265534" />
            <inertia ixx="1.433657e-4" ixy="-5.220000e-8" ixz="5.026000e-7" iyy="1.455343e-4" iyz="-1.360000e-8" izz="2.086642e-4" />
        </inertial>
    </link>
    <joint name="a_torobo_arm/joint_tip" type="fixed">
        <parent link="a_torobo_arm/link_7" />
        <child link="a_torobo_arm/link_tip" />
        <origin rpy="0 0 0" xyz="0 0 0" />
    </joint>
    <link name="a_torobo_arm/link_tip" />
    <!-- Link1 -->
    <gazebo reference="a_torobo_arm/link_1">
        <mu1>0.2</mu1>
        <mu2>0.2</mu2>
    </gazebo>
    <!-- Link2 -->
    <gazebo reference="a_torobo_arm/link_2">
        <mu1>0.2</mu1>
        <mu2>0.2</mu2>
    </gazebo>
    <!-- Link3 -->
    <gazebo reference="a_torobo_arm/link_3">
        <mu1>0.2</mu1>
        <mu2>0.2</mu2>
    </gazebo>
    <!-- Link4 -->
    <gazebo reference="a_torobo_arm/link_4">
        <mu1>0.2</mu1>
        <mu2>0.2</mu2>
    </gazebo>
    <!-- Link5 -->
    <gazebo reference="a_torobo_arm/link_5">
        <mu1>0.2</mu1>
        <mu2>0.2</mu2>
    </gazebo>
    <!-- Link6 -->
    <gazebo reference="a_torobo_arm/link_6">
        <mu1>0.2</mu1>
        <mu2>0.2</mu2>
    </gazebo>
    <!-- Link7 -->
    <gazebo reference="a_torobo_arm/link_7">
        <mu1>0.2</mu1>
        <mu2>0.2</mu2>
    </gazebo>
    <!-- EE Link -->
    <gazebo reference="a_torobo_arm/link_tip">
        <mu1>0.2</mu1>
        <mu2>0.2</mu2>
    </gazebo>
    <!-- =============== Transmission =============== -->
    <simple_transmission name="a_torobo_arm/joint_1" reduction="1" />
    <simple_transmission name="a_torobo_arm/joint_2" reduction="1" />
    <simple_transmission name="a_torobo_arm/joint_3" reduction="1" />
    <simple_transmission name="a_torobo_arm/joint_4" reduction="1" />
    <simple_transmission name="a_torobo_arm/joint_5" reduction="1" />
    <simple_transmission name="a_torobo_arm/joint_6" reduction="1" />
    <simple_transmission name="a_torobo_arm/joint_7" reduction="1" />
    <link name="a_torobo_arm/ee_link" />
    <joint name="a_torobo_arm/ee_joint" type="fixed">
        <parent link="a_torobo_arm/link_7" />
        <child link="a_torobo_arm/ee_link" />
        <origin rpy="0 -1.5707963267948966 0" xyz="0 0 0" />
    </joint>
    <joint name="b_torobo_arm/root" type="fixed">
        <origin rpy="0 0 -1.5707963267948966" xyz="0 0.4875 0.785" />
        <parent link="ground" />
        <child link="b_torobo_arm/link_0" />
    </joint>
    <link name="b_torobo_arm/link_0">
        <visual>
            <geometry>
                <mesh filename="package://torobo_resources/meshes/arm/TRBA-R-002-7/link0.dae" scale="0.01 0.01 0.01" />
            </geometry>
            <origin xyz="0 0 0" />
        </visual>
        <collision>
            <geometry>
                <mesh filename="package://torobo_resources/meshes/arm/TRBA-R-002-7/link0.dae" scale="0.012 0.012 0.012" />
            </geometry>
            <origin xyz="0 0 0" />
        </collision>
        <inertial>
            <origin xyz="-0.000436 0.000019 0.041708" rpy="0 0 0" />
            <mass value="2.545036" />
            <inertia ixx="6.331898e-3" ixy="2.399900e-6" ixz="-3.132040e-5" iyy="6.434612e-3" iyz="1.515900e-6" izz="8.449834e-3" />
        </inertial>
    </link>
    <joint name="b_torobo_arm/joint_1" type="revolute">
        <parent link="b_torobo_arm/link_0" />
        <child link="b_torobo_arm/link_1" />
        <origin rpy="0 0 0" xyz="0 0 0.220" />
        <axis xyz="0 0 1" />
        <limit effort="110" lower="-2.9670597283903604" upper="2.9670597283903604" velocity="1.7453292519943295" />
    </joint>
    <link name="b_torobo_arm/link_1">
        <visual>
            <geometry>
                <mesh filename="package://torobo_resources/meshes/arm/TRBA-R-002-7/link1.dae" scale="0.01 0.01 0.01" />
            </geometry>
        </visual>
        <collision>
            <geometry>
                <mesh filename="package://torobo_resources/meshes/arm/TRBA-R-002-7/link1.dae" scale="0.012 0.012 0.012" />
            </geometry>
        </collision>
        <inertial>
            <origin xyz="0.000009 0.004526 -0.062965" rpy="0 0 0" />
            <mass value="4.553552" />
            <inertia ixx="2.644887e-2" ixy="5.349000e-7" ixz="4.084800e-6" iyy="2.675988e-2" iyz="-8.294709e-4" izz="7.305179e-3" />
        </inertial>
    </link>
    <joint name="b_torobo_arm/joint_2" type="revolute">
        <parent link="b_torobo_arm/link_1" />
        <child link="b_torobo_arm/link_2" />
        <origin rpy="-1.5707963267948966 0 0" xyz="0 0 0" />
        <axis xyz="0 0 1" />
        <limit effort="110" lower="-1.9198621771937625" upper="1.9198621771937625" velocity="1.7453292519943295" />
    </joint>
    <link name="b_torobo_arm/link_2">
        <visual>
            <geometry>
                <mesh filename="package://torobo_resources/meshes/arm/TRBA-R-002-7/link2.dae" scale="0.01 0.01 0.01" />
            </geometry>
        </visual>
        <collision>
            <geometry>
                <mesh filename="package://torobo_resources/meshes/arm/TRBA-R-002-7/link2.dae" scale="0.012 0.012 0.012" />
            </geometry>
        </collision>
        <inertial>
            <origin xyz="0.000000 -0.064474 -0.016924" rpy="0 0 0" />
            <mass value="2.474676" />
            <inertia ixx="1.163631e-2" ixy="-6.892000e-7" ixz="2.103000e-7" iyy="4.853435e-3" iyz="2.196366e-3" izz="1.202305e-2" />
        </inertial>
    </link>
    <joint name="b_torobo_arm/joint_3" type="revolute">
        <parent link="b_torobo_arm/link_2" />
        <child link="b_torobo_arm/link_3" />
        <origin rpy="1.5707963267948966 0 0" xyz="0 -0.3 0" />
        <axis xyz="0 0 1" />
        <limit effort="70" lower="-2.8797932657906435" upper="2.8797932657906435" velocity="2.0943951023931953" />
    </joint>
    <link name="b_torobo_arm/link_3">
        <visual>
            <geometry>
                <mesh filename="package://torobo_resources/meshes/arm/TRBA-R-002-7/link3.dae" scale="0.01 0.01 0.01" />
            </geometry>
        </visual>
        <collision>
            <geometry>
                <mesh filename="package://torobo_resources/meshes/arm/TRBA-R-002-7/link3.dae" scale="0.012 0.012 0.012" />
            </geometry>
        </collision>
        <inertial>
            <origin xyz="0.000012 0.005769 -0.066866" rpy="0 0 0" />
            <mass value="3.237919" />
            <inertia ixx="1.911238e-2" ixy="2.978000e-7" ixz="-4.962600e-6" iyy="1.915428e-2" iyz="-7.716287e-4" izz="3.920768e-3" />
        </inertial>
    </link>
    <joint name="b_torobo_arm/joint_4" type="revolute">
        <parent link="b_torobo_arm/link_3" />
        <child link="b_torobo_arm/link_4" />
        <origin rpy="-1.5707963267948966 0 0" xyz="0 0 0" />
        <axis xyz="0 0 1" />
        <limit effort="70" lower="-2.1816615649929116" upper="2.1816615649929116" velocity="2.0943951023931953" />
    </joint>
    <link name="b_torobo_arm/link_4">
        <visual>
            <geometry>
                <mesh filename="package://torobo_resources/meshes/arm/TRBA-R-002-7/link4.dae" scale="0.01 0.01 0.01" />
            </geometry>
        </visual>
        <collision>
            <geometry>
                <mesh filename="package://torobo_resources/meshes/arm/TRBA-R-002-7/link4.dae" scale="0.012 0.012 0.012" />
            </geometry>
        </collision>
        <inertial>
            <origin xyz="0.000006 -0.062765 -0.018379" rpy="0 0 0" />
            <mass value="1.945562" />
            <inertia ixx="9.626170e-3" ixy="-1.551000e-7" ixz="1.278000e-7" iyy="2.996661e-3" iyz="1.733720e-3" izz="9.870906e-3" />
        </inertial>
    </link>
    <joint name="b_torobo_arm/joint_5" type="revolute">
        <parent link="b_torobo_arm/link_4" />
        <child link="b_torobo_arm/link_5" />
        <origin rpy="1.5707963267948966 0 0" xyz="0 -0.3 0" />
        <axis xyz="0 0 1" />
        <limit effort="30" lower="-2.8797932657906435" upper="2.8797932657906435" velocity="2.792526803190927" />
    </joint>
    <link name="b_torobo_arm/link_5">
        <visual>
            <geometry>
                <mesh filename="package://torobo_resources/meshes/arm/TRBA-R-002-7/link5.dae" scale="0.01 0.01 0.01" />
            </geometry>
        </visual>
        <collision>
            <geometry>
                <mesh filename="package://torobo_resources/meshes/arm/TRBA-R-002-7/link5.dae" scale="0.012 0.012 0.012" />
            </geometry>
        </collision>
        <inertial>
            <origin xyz="-0.000009 0.010041 -0.094026" rpy="0 0 0" />
            <mass value="1.798056" />
            <inertia ixx="9.196412e-3" ixy="2.212000e-7" ixz="6.890000e-7" iyy="9.130626e-3" iyz="-1.559966e-3" izz="1.957429e-3" />
        </inertial>
    </link>
    <joint name="b_torobo_arm/joint_6" type="revolute">
        <parent link="b_torobo_arm/link_5" />
        <child link="b_torobo_arm/link_6" />
        <origin rpy="-1.5707963267948966 0 0" xyz="0 0 0" />
        <axis xyz="0 0 1" />
        <limit effort="30" lower="-2.0943951023931953" upper="2.0943951023931953" velocity="2.792526803190927" />
    </joint>
    <link name="b_torobo_arm/link_6">
        <visual>
            <geometry>
                <mesh filename="package://torobo_resources/meshes/arm/TRBA-R-002-7/link6.dae" scale="0.01 0.01 0.01" />
            </geometry>
        </visual>
        <collision>
            <geometry>
                <mesh filename="package://torobo_resources/meshes/arm/TRBA-R-002-7/link6.dae" scale="0.012 0.012 0.012" />
            </geometry>
        </collision>
        <inertial>
            <origin xyz="0.000002 -0.050748 -0.002319" rpy="0 0 0" />
            <mass value="2.271792" />
            <inertia ixx="8.528173e-3" ixy="-5.321000e-7" ixz="4.298000e-7" iyy="2.242304e-3" iyz="1.159234e-4" izz="8.444133e-3" />
        </inertial>
    </link>
    <joint name="b_torobo_arm/joint_7" type="revolute">
        <parent link="b_torobo_arm/link_6" />
        <child link="b_torobo_arm/link_7" />
        <origin rpy="1.5707963267948966 0 0" xyz="0 -0.170 0" />
        <axis xyz="0 0 1" />
        <limit effort="15" lower="-2.9670597283903604" upper="2.9670597283903604" velocity="4.1887902047863905" />
    </joint>
    <link name="b_torobo_arm/link_7">
        <visual>
            <geometry>
                <mesh filename="package://torobo_resources/meshes/arm/TRBA-R-002-7/link7.dae" scale="0.01 0.01 0.01" />
            </geometry>
        </visual>
        <collision>
            <geometry>
                <mesh filename="package://torobo_resources/meshes/arm/TRBA-R-002-7/link7.dae" scale="0.012 0.012 0.012" />
            </geometry>
        </collision>
        <inertial>
            <origin xyz="-0.000973 0.000022 -0.017659" rpy="0 0 0" />
            <mass value="0.265534" />
            <inertia ixx="1.433657e-4" ixy="-5.220000e-8" ixz="5.026000e-7" iyy="1.455343e-4" iyz="-1.360000e-8" izz="2.086642e-4" />
        </inertial>
    </link>
    <joint name="b_torobo_arm/joint_tip" type="fixed">
        <parent link="b_torobo_arm/link_7" />
        <child link="b_torobo_arm/link_tip" />
        <origin rpy="0 0 0" xyz="0 0 0" />
    </joint>
    <link name="b_torobo_arm/link_tip" />
    <!-- Link1 -->
    <gazebo reference="b_torobo_arm/link_1">
        <mu1>0.2</mu1>
        <mu2>0.2</mu2>
    </gazebo>
    <!-- Link2 -->
    <gazebo reference="b_torobo_arm/link_2">
        <mu1>0.2</mu1>
        <mu2>0.2</mu2>
    </gazebo>
    <!-- Link3 -->
    <gazebo reference="b_torobo_arm/link_3">
        <mu1>0.2</mu1>
        <mu2>0.2</mu2>
    </gazebo>
    <!-- Link4 -->
    <gazebo reference="b_torobo_arm/link_4">
        <mu1>0.2</mu1>
        <mu2>0.2</mu2>
    </gazebo>
    <!-- Link5 -->
    <gazebo reference="b_torobo_arm/link_5">
        <mu1>0.2</mu1>
        <mu2>0.2</mu2>
    </gazebo>
    <!-- Link6 -->
    <gazebo reference="b_torobo_arm/link_6">
        <mu1>0.2</mu1>
        <mu2>0.2</mu2>
    </gazebo>
    <!-- Link7 -->
    <gazebo reference="b_torobo_arm/link_7">
        <mu1>0.2</mu1>
        <mu2>0.2</mu2>
    </gazebo>
    <!-- EE Link -->
    <gazebo reference="b_torobo_arm/link_tip">
        <mu1>0.2</mu1>
        <mu2>0.2</mu2>
    </gazebo>
    <!-- =============== Transmission =============== -->
    <simple_transmission name="b_torobo_arm/joint_1" reduction="1" />
    <simple_transmission name="b_torobo_arm/joint_2" reduction="1" />
    <simple_transmission name="b_torobo_arm/joint_3" reduction="1" />
    <simple_transmission name="b_torobo_arm/joint_4" reduction="1" />
    <simple_transmission name="b_torobo_arm/joint_5" reduction="1" />
    <simple_transmission name="b_torobo_arm/joint_6" reduction="1" />
    <simple_transmission name="b_torobo_arm/joint_7" reduction="1" />
    <link name="b_torobo_arm/ee_link" />
    <joint name="b_torobo_arm/ee_joint" type="fixed">
        <parent link="b_torobo_arm/link_7" />
        <child link="b_torobo_arm/ee_link" />
        <origin rpy="0 -1.5707963267948966 0" xyz="0 0 0" />
    </joint>
    <link name="a_torobo_gripper/base_link" />
    <joint name="a_torobo_gripper_parent_base_joint" type="fixed">
        <parent link="a_torobo_arm/ee_link" />
        <child link="a_torobo_gripper/base_link" />
        <origin rpy="0 0 0" xyz="0 0 0" />
    </joint>
    <joint name="a_torobo_gripper/gripper_base_joint" type="fixed">
        <origin rpy="0 1.5707963267948966 0" xyz="0 0 0" />
        <parent link="a_torobo_gripper/base_link" />
        <child link="a_torobo_gripper/gripper_base" />
    </joint>
    <link name="a_torobo_gripper/gripper_base">
        <visual>
            <geometry>
                <mesh filename="package://torobo_resources/meshes/gripper/TRBG-L-B-001/DAE/gripper_base.dae" scale="0.01 0.01 0.01" />
            </geometry>
            <material name="white" />
            <origin rpy="0 0 1.5707963267948966" xyz="0 0 0" />
        </visual>
        <collision>
            <geometry>
                <mesh filename="package://torobo_resources/meshes/gripper/TRBG-L-B-001/STL/gripper_base.stl" scale="0.01 0.01 0.01" />
            </geometry>
            <origin rpy="0 0 1.5707963267948966" xyz="0 0 0" />
        </collision>
        <inertial>
            <origin rpy="0 0 0" xyz="0 -0.007 0.046" />
            <mass value="0.76" />
            <inertia ixx="1.104105e-3" ixy="2.054322e-5" ixz="-5.411983e-6" iyy="7.765804e-4" iyz="3.247528e-5" izz="6.346240e-4" />
        </inertial>
    </link>
    <link name="a_torobo_gripper/grasping_frame">
        <visual>
            <origin rpy="0 0 0" xyz="0 0 0" />
            <geometry>
                <box size="0.02 0.02 0.02" />
            </geometry>
            <material name="clear_color" />
        </visual>
        <!--
      <collision>
        <origin xyz="0 0 0" rpy="0 0 0"/>
        <geometry>
          <box size="0.02 0.02 0.02" />
        </geometry>
      </collision>
      -->
    </link>
    <joint name="a_torobo_gripper/grasping_frame_joint" type="fixed">
        <parent link="a_torobo_gripper/gripper_base" />
        <child link="a_torobo_gripper/grasping_frame" />
        <origin rpy="0 0 0" xyz="0 0 0.16" />
    </joint>
    <link name="a_torobo_gripper/finger_link">
        <visual>
            <origin rpy="0 0 -1.5707963267948966" xyz="0 0 0" />
            <geometry>
                <mesh filename="package://torobo_resources/meshes/gripper/TRBG-L-B-001/DAE/finger.dae" scale="0.01 0.01 0.01" />
            </geometry>
            <material name="light_grey" />
        </visual>
        <collision>
            <origin rpy="0 0 -1.5707963267948966" xyz="0 0 0" />
            <geometry>
                <mesh filename="package://torobo_resources/meshes/gripper/TRBG-L-B-001/STL/finger.stl" scale="0.01 0.01 0.01" />
            </geometry>
        </collision>
        <inertial>
            <origin rpy="0 0 0" xyz="0 0.007 0.046" />
            <mass value="0.03" />
            <inertia ixx="0.0004" ixy="0" ixz="0" iyy="0.0004" iyz="0" izz="0.0004" />
        </inertial>
    </link>
    <link name="a_torobo_gripper/mimic_link">
        <visual>
            <origin rpy="0 0 -1.5707963267948966" xyz="0 0 0" />
            <geometry>
                <mesh filename="package://torobo_resources/meshes/gripper/TRBG-L-B-001/DAE/finger.dae" scale="0.01 0.01 0.01" />
            </geometry>
            <material name="light_grey" />
        </visual>
        <collision>
            <origin rpy="0 0 -1.5707963267948966" xyz="0 0 0" />
            <geometry>
                <mesh filename="package://torobo_resources/meshes/gripper/TRBG-L-B-001/STL/finger.stl" scale="0.01 0.01 0.01" />
            </geometry>
        </collision>
        <inertial>
            <origin rpy="0 0 0" xyz="0 -0.007 0.046" />
            <mass value="0.03" />
            <inertia ixx="0.0004" ixy="0" ixz="0" iyy="0.0004" iyz="0" izz="0.0004" />
        </inertial>
    </link>
    <joint name="a_torobo_gripper/finger_joint" type="prismatic">
        <parent link="a_torobo_gripper/mimic_link" />
        <child link="a_torobo_gripper/finger_link" />
        <origin rpy="0 0 3.141592653589793" xyz="0 0 0" />
        <axis xyz="0 1 0" />
        <limit effort="50" lower="0" upper="0.08" velocity="0.5" />
    </joint>
    <joint name="a_torobo_gripper/mimic_joint" type="prismatic">
        <parent link="a_torobo_gripper/gripper_base" />
        <child link="a_torobo_gripper/mimic_link" />
        <origin rpy="0 0 0" xyz="0 0 0" />
        <axis xyz="0 1 0" />
        <limit effort="50" lower="0" upper="0.04" velocity="0.5" />
        <mimic joint="a_torobo_gripper/finger_joint" multiplier="0.5" offset="0.0" />
    </joint>
    <!-- ros_control plugin -->
    <gazebo />
    <!-- grasping_frame -->
    <gazebo reference="a_torobo_gripper/grasping_frame">
        <mu1>0.2</mu1>
        <mu2>0.2</mu2>
    </gazebo>
    <!-- gripper_base -->
    <gazebo reference="a_torobo_gripper/gripper_base">
        <mu1>0.2</mu1>
        <mu2>0.2</mu2>
    </gazebo>
    <!-- right_finger -->
    <gazebo reference="a_torobo_gripper/finger_joint">
        <mu1>0.2</mu1>
        <mu2>0.2</mu2>
    </gazebo>
    <!-- left_finger -->
    <gazebo reference="a_torobo_gripper/mimic_joint">
        <mu1>0.2</mu1>
        <mu2>0.2</mu2>
    </gazebo>
    <!-- =============== Transmission =============== -->
    <simple_transmission name="a_torobo_gripper/finger_joint" reduction="1" />
    <simple_transmission name="a_torobo_gripper/mimic_joint" reduction="1" />
    <link name="a_torobo_gripper/tip_link" />
    <joint name="a_torobo_gripper/tip_joint" type="fixed">
        <parent link="a_torobo_gripper/grasping_frame" />
        <child link="a_torobo_gripper/tip_link" />
        <origin rpy="3.141592653589793 0 3.141592653589793" xyz="0 0 0.025" />
    </joint>
    <link name="b_torobo_gripper/base_link" />
    <joint name="b_torobo_gripper_parent_base_joint" type="fixed">
        <parent link="b_torobo_arm/ee_link" />
        <child link="b_torobo_gripper/base_link" />
        <origin rpy="0 0 0" xyz="0 0 0" />
    </joint>
    <joint name="b_torobo_gripper/gripper_base_joint" type="fixed">
        <origin rpy="0 1.5707963267948966 0" xyz="0 0 0" />
        <parent link="b_torobo_gripper/base_link" />
        <child link="b_torobo_gripper/gripper_base" />
    </joint>
    <link name="b_torobo_gripper/gripper_base">
        <visual>
            <geometry>
                <mesh filename="package://torobo_resources/meshes/gripper/TRBG-L-B-001/DAE/gripper_base.dae" scale="0.01 0.01 0.01" />
            </geometry>
            <material name="white" />
            <origin rpy="0 0 1.5707963267948966" xyz="0 0 0" />
        </visual>
        <collision>
            <geometry>
                <mesh filename="package://torobo_resources/meshes/gripper/TRBG-L-B-001/STL/gripper_base.stl" scale="0.01 0.01 0.01" />
            </geometry>
            <origin rpy="0 0 1.5707963267948966" xyz="0 0 0" />
        </collision>
        <inertial>
            <origin rpy="0 0 0" xyz="0 -0.007 0.046" />
            <mass value="0.76" />
            <inertia ixx="1.104105e-3" ixy="2.054322e-5" ixz="-5.411983e-6" iyy="7.765804e-4" iyz="3.247528e-5" izz="6.346240e-4" />
        </inertial>
    </link>
    <link name="b_torobo_gripper/grasping_frame">
        <visual>
            <origin rpy="0 0 0" xyz="0 0 0" />
            <geometry>
                <box size="0.02 0.02 0.02" />
            </geometry>
            <material name="clear_color" />
        </visual>
        <!--
      <collision>
        <origin xyz="0 0 0" rpy="0 0 0"/>
        <geometry>
          <box size="0.02 0.02 0.02" />
        </geometry>
      </collision>
      -->
    </link>
    <joint name="b_torobo_gripper/grasping_frame_joint" type="fixed">
        <parent link="b_torobo_gripper/gripper_base" />
        <child link="b_torobo_gripper/grasping_frame" />
        <origin rpy="0 0 0" xyz="0 0 0.16" />
    </joint>
    <link name="b_torobo_gripper/finger_link">
        <visual>
            <origin rpy="0 0 -1.5707963267948966" xyz="0 0 0" />
            <geometry>
                <mesh filename="package://torobo_resources/meshes/gripper/TRBG-L-B-001/DAE/finger.dae" scale="0.01 0.01 0.01" />
            </geometry>
            <material name="light_grey" />
        </visual>
        <collision>
            <origin rpy="0 0 -1.5707963267948966" xyz="0 0 0" />
            <geometry>
                <mesh filename="package://torobo_resources/meshes/gripper/TRBG-L-B-001/STL/finger.stl" scale="0.01 0.01 0.01" />
            </geometry>
        </collision>
        <inertial>
            <origin rpy="0 0 0" xyz="0 0.007 0.046" />
            <mass value="0.03" />
            <inertia ixx="0.0004" ixy="0" ixz="0" iyy="0.0004" iyz="0" izz="0.0004" />
        </inertial>
    </link>
    <link name="b_torobo_gripper/mimic_link">
        <visual>
            <origin rpy="0 0 -1.5707963267948966" xyz="0 0 0" />
            <geometry>
                <mesh filename="package://torobo_resources/meshes/gripper/TRBG-L-B-001/DAE/finger.dae" scale="0.01 0.01 0.01" />
            </geometry>
            <material name="light_grey" />
        </visual>
        <collision>
            <origin rpy="0 0 -1.5707963267948966" xyz="0 0 0" />
            <geometry>
                <mesh filename="package://torobo_resources/meshes/gripper/TRBG-L-B-001/STL/finger.stl" scale="0.01 0.01 0.01" />
            </geometry>
        </collision>
        <inertial>
            <origin rpy="0 0 0" xyz="0 -0.007 0.046" />
            <mass value="0.03" />
            <inertia ixx="0.0004" ixy="0" ixz="0" iyy="0.0004" iyz="0" izz="0.0004" />
        </inertial>
    </link>
    <joint name="b_torobo_gripper/finger_joint" type="prismatic">
        <parent link="b_torobo_gripper/mimic_link" />
        <child link="b_torobo_gripper/finger_link" />
        <origin rpy="0 0 3.141592653589793" xyz="0 0 0" />
        <axis xyz="0 1 0" />
        <limit effort="50" lower="0" upper="0.08" velocity="0.5" />
    </joint>
    <joint name="b_torobo_gripper/mimic_joint" type="prismatic">
        <parent link="b_torobo_gripper/gripper_base" />
        <child link="b_torobo_gripper/mimic_link" />
        <origin rpy="0 0 0" xyz="0 0 0" />
        <axis xyz="0 1 0" />
        <limit effort="50" lower="0" upper="0.04" velocity="0.5" />
        <mimic joint="b_torobo_gripper/finger_joint" multiplier="0.5" offset="0.0" />
    </joint>
    <!-- ros_control plugin -->
    <gazebo />
    <!-- grasping_frame -->
    <gazebo reference="b_torobo_gripper/grasping_frame">
        <mu1>0.2</mu1>
        <mu2>0.2</mu2>
    </gazebo>
    <!-- gripper_base -->
    <gazebo reference="b_torobo_gripper/gripper_base">
        <mu1>0.2</mu1>
        <mu2>0.2</mu2>
    </gazebo>
    <!-- right_finger -->
    <gazebo reference="b_torobo_gripper/finger_joint">
        <mu1>0.2</mu1>
        <mu2>0.2</mu2>
    </gazebo>
    <!-- left_finger -->
    <gazebo reference="b_torobo_gripper/mimic_joint">
        <mu1>0.2</mu1>
        <mu2>0.2</mu2>
    </gazebo>
    <!-- =============== Transmission =============== -->
    <simple_transmission name="b_torobo_gripper/finger_joint" reduction="1" />
    <simple_transmission name="b_torobo_gripper/mimic_joint" reduction="1" />
    <link name="b_torobo_gripper/tip_link" />
    <joint name="b_torobo_gripper/tip_joint" type="fixed">
        <parent link="b_torobo_gripper/grasping_frame" />
        <child link="b_torobo_gripper/tip_link" />
        <origin rpy="3.141592653589793 0 3.141592653589793" xyz="0 0 0.025" />
    </joint>
    <joint name="b_phoxi_m_camera_link_joint" type="fixed">
        <parent link="ground" />
        <child link="b_phoxi_m_camera_link" />
        <origin rpy="0.0 1.1 3.14" xyz="0.5 0.0 1.67" />
    </joint>
    <joint name="b_phoxi_m_camera_reference_joint" type="fixed">
        <parent link="b_phoxi_m_camera_link" />
        <child link="b_phoxi_m_camera_reference" />
        <origin rpy="0 0 0.20507618710933373" xyz="0.002164826095 -0.176277236938477 0.0299" />
    </joint>
    <link name="b_phoxi_m_camera_link">
        <visual>
            <!-- <origin xyz="0 0 0" rpy="0 1.5707 0" /> -->
            <origin rpy="0 0 0" xyz="0 0 0" />
            <geometry>
                <mesh filename="package://aist_phoxi_camera/meshes/visual/PhoXi_M.f.STL" scale="0.001 0.001 0.001" />
            </geometry>
            <material name="">
                <color rgba="0.8 0.8 0.8 1" />
            </material>
        </visual>
        <collision>
            <!-- <origin xyz="0 0 0" rpy="0 1.5707 0" /> -->
            <origin rpy="0 0 0" xyz="0 0 0" />
            <geometry>
                <mesh filename="package://aist_phoxi_camera/meshes/collision/PhoXi_M.c.STL" scale="0.001 0.001 0.001" />
            </geometry>
        </collision>
        <inertial>
            <mass value="0.1" />
            <origin xyz="0 0 0" rpy="0 0 0" />
            <inertia ixx="0.03" iyy="0.03" izz="0.03" ixy="0.0" ixz="0.0" iyz="0.0" />
        </inertial>
    </link>
    <link name="b_phoxi_m_camera_reference" />
    <link name="b_phoxi_m_camera_sensor" />
    <joint name="b_phoxi_m_camera_sensor_joint" type="fixed">
        <parent link="b_phoxi_m_camera_reference" />
        <child link="b_phoxi_m_camera_sensor" />
        <origin rpy="-1.5707963267948966 0 -1.5707963267948966" xyz="0 0 0" />
    </joint>
    <gazebo reference="b_phoxi_m_camera_reference">
        <sensor name="b_phoxi_m_camera" type="depth">
            <always_on>true</always_on>
            <visualize>true</visualize>
            <camera>
                <image>
                    <width>2064</width>
                    <height>1544</height>
                    <format>L8</format>
                </image>
                <horizontal_fov>0.9077</horizontal_fov>
                <depth_camera />
                <clip>
                    <near>0.1</near>
                    <far>100</far>
                </clip>
            </camera>
            <plugin filename="libgazebo_ros_openni_kinect.so" name="b_phoxi_m_camera_controller">
                <baseline>0.35</baseline>
                <alwaysOn>true</alwaysOn>
                <updateRate>2.5</updateRate>
                <cameraName>b_phoxi_m_camera</cameraName>
                <frameName>b_phoxi_m_camera_sensor</frameName>
                <imageTopicName>texture</imageTopicName>
                <depthImageTopicName>depth_map</depthImageTopicName>
                <pointCloudTopicName>pointcloud</pointCloudTopicName>
                <cameraInfoTopicName>camera_info</cameraInfoTopicName>
                <depthImageCameraInfoTopicName>camera_info</depthImageCameraInfoTopicName>
                <pointCloudCutoff>0.4</pointCloudCutoff>
                <!-- <hackBaseline>0.35</hackBaseline> -->
                <distortionK1>0.0</distortionK1>
                <distortionK2>0.0</distortionK2>
                <distortionK3>0.0</distortionK3>
                <distortionT1>0.0</distortionT1>
                <distortionT2>0.0</distortionT2>
                <CxPrime>0.0</CxPrime>
                <Cx>0.0</Cx>
                <Cy>0.0</Cy>
                <focalLength>0.0</focalLength>
            </plugin>
        </sensor>
    </gazebo>
    <!-- I would like to remove the "world" link definition, but apparently it is necessary for Gazebo -->
    <link name="world" />
    <joint name="world_ground_joint" type="fixed">
        <parent link="world" />
        <child link="ground" />
        <origin rpy="0 0 0" xyz="0 0 0" />
    </joint>
    <transmission name="trans_a_torobo_arm/joint_1">
        <type>transmission_interface/SimpleTransmission</type>
        <joint name="a_torobo_arm/joint_1">
            <hardwareInterface>hardware_interface/EffortJointInterface</hardwareInterface>
        </joint>
        <actuator name="a_torobo_arm/joint_1_motor">
            <hardwareInterface>hardware_interface/EffortJointInterface</hardwareInterface>
            <mechanicalReduction>1</mechanicalReduction>
        </actuator>
    </transmission>
    <transmission name="trans_a_torobo_arm/joint_2">
        <type>transmission_interface/SimpleTransmission</type>
        <joint name="a_torobo_arm/joint_2">
            <hardwareInterface>hardware_interface/EffortJointInterface</hardwareInterface>
        </joint>
        <actuator name="a_torobo_arm/joint_2_motor">
            <hardwareInterface>hardware_interface/EffortJointInterface</hardwareInterface>
            <mechanicalReduction>1</mechanicalReduction>
        </actuator>
    </transmission>
    <transmission name="trans_a_torobo_arm/joint_3">
        <type>transmission_interface/SimpleTransmission</type>
        <joint name="a_torobo_arm/joint_3">
            <hardwareInterface>hardware_interface/EffortJointInterface</hardwareInterface>
        </joint>
        <actuator name="a_torobo_arm/joint_3_motor">
            <hardwareInterface>hardware_interface/EffortJointInterface</hardwareInterface>
            <mechanicalReduction>1</mechanicalReduction>
        </actuator>
    </transmission>
    <transmission name="trans_a_torobo_arm/joint_4">
        <type>transmission_interface/SimpleTransmission</type>
        <joint name="a_torobo_arm/joint_4">
            <hardwareInterface>hardware_interface/EffortJointInterface</hardwareInterface>
        </joint>
        <actuator name="a_torobo_arm/joint_4_motor">
            <hardwareInterface>hardware_interface/EffortJointInterface</hardwareInterface>
            <mechanicalReduction>1</mechanicalReduction>
        </actuator>
    </transmission>
    <transmission name="trans_a_torobo_arm/joint_5">
        <type>transmission_interface/SimpleTransmission</type>
        <joint name="a_torobo_arm/joint_5">
            <hardwareInterface>hardware_interface/EffortJointInterface</hardwareInterface>
        </joint>
        <actuator name="a_torobo_arm/joint_5_motor">
            <hardwareInterface>hardware_interface/EffortJointInterface</hardwareInterface>
            <mechanicalReduction>1</mechanicalReduction>
        </actuator>
    </transmission>
    <transmission name="trans_a_torobo_arm/joint_6">
        <type>transmission_interface/SimpleTransmission</type>
        <joint name="a_torobo_arm/joint_6">
            <hardwareInterface>hardware_interface/EffortJointInterface</hardwareInterface>
        </joint>
        <actuator name="a_torobo_arm/joint_6_motor">
            <hardwareInterface>hardware_interface/EffortJointInterface</hardwareInterface>
            <mechanicalReduction>1</mechanicalReduction>
        </actuator>
    </transmission>
    <transmission name="trans_a_torobo_arm/joint_7">
        <type>transmission_interface/SimpleTransmission</type>
        <joint name="a_torobo_arm/joint_7">
            <hardwareInterface>hardware_interface/EffortJointInterface</hardwareInterface>
        </joint>
        <actuator name="a_torobo_arm/joint_7_motor">
            <hardwareInterface>hardware_interface/EffortJointInterface</hardwareInterface>
            <mechanicalReduction>1</mechanicalReduction>
        </actuator>
    </transmission>
    <transmission name="trans_b_torobo_arm/joint_1">
        <type>transmission_interface/SimpleTransmission</type>
        <joint name="b_torobo_arm/joint_1">
            <hardwareInterface>hardware_interface/EffortJointInterface</hardwareInterface>
        </joint>
        <actuator name="b_torobo_arm/joint_1_motor">
            <hardwareInterface>hardware_interface/EffortJointInterface</hardwareInterface>
            <mechanicalReduction>1</mechanicalReduction>
        </actuator>
    </transmission>
    <transmission name="trans_b_torobo_arm/joint_2">
        <type>transmission_interface/SimpleTransmission</type>
        <joint name="b_torobo_arm/joint_2">
            <hardwareInterface>hardware_interface/EffortJointInterface</hardwareInterface>
        </joint>
        <actuator name="b_torobo_arm/joint_2_motor">
            <hardwareInterface>hardware_interface/EffortJointInterface</hardwareInterface>
            <mechanicalReduction>1</mechanicalReduction>
        </actuator>
    </transmission>
    <transmission name="trans_b_torobo_arm/joint_3">
        <type>transmission_interface/SimpleTransmission</type>
        <joint name="b_torobo_arm/joint_3">
            <hardwareInterface>hardware_interface/EffortJointInterface</hardwareInterface>
        </joint>
        <actuator name="b_torobo_arm/joint_3_motor">
            <hardwareInterface>hardware_interface/EffortJointInterface</hardwareInterface>
            <mechanicalReduction>1</mechanicalReduction>
        </actuator>
    </transmission>
    <transmission name="trans_b_torobo_arm/joint_4">
        <type>transmission_interface/SimpleTransmission</type>
        <joint name="b_torobo_arm/joint_4">
            <hardwareInterface>hardware_interface/EffortJointInterface</hardwareInterface>
        </joint>
        <actuator name="b_torobo_arm/joint_4_motor">
            <hardwareInterface>hardware_interface/EffortJointInterface</hardwareInterface>
            <mechanicalReduction>1</mechanicalReduction>
        </actuator>
    </transmission>
    <transmission name="trans_b_torobo_arm/joint_5">
        <type>transmission_interface/SimpleTransmission</type>
        <joint name="b_torobo_arm/joint_5">
            <hardwareInterface>hardware_interface/EffortJointInterface</hardwareInterface>
        </joint>
        <actuator name="b_torobo_arm/joint_5_motor">
            <hardwareInterface>hardware_interface/EffortJointInterface</hardwareInterface>
            <mechanicalReduction>1</mechanicalReduction>
        </actuator>
    </transmission>
    <transmission name="trans_b_torobo_arm/joint_6">
        <type>transmission_interface/SimpleTransmission</type>
        <joint name="b_torobo_arm/joint_6">
            <hardwareInterface>hardware_interface/EffortJointInterface</hardwareInterface>
        </joint>
        <actuator name="b_torobo_arm/joint_6_motor">
            <hardwareInterface>hardware_interface/EffortJointInterface</hardwareInterface>
            <mechanicalReduction>1</mechanicalReduction>
        </actuator>
    </transmission>
    <transmission name="trans_b_torobo_arm/joint_7">
        <type>transmission_interface/SimpleTransmission</type>
        <joint name="b_torobo_arm/joint_7">
            <hardwareInterface>hardware_interface/EffortJointInterface</hardwareInterface>
        </joint>
        <actuator name="b_torobo_arm/joint_7_motor">
            <hardwareInterface>hardware_interface/EffortJointInterface</hardwareInterface>
            <mechanicalReduction>1</mechanicalReduction>
        </actuator>
    </transmission>
    <transmission name="trans_a_torobo_gripper/finger_joint">
        <type>transmission_interface/SimpleTransmission</type>
        <joint name="a_torobo_gripper/finger_joint">
            <hardwareInterface>hardware_interface/EffortJointInterface</hardwareInterface>
        </joint>
        <actuator name="a_torobo_gripper/finger_joint_motor">
            <hardwareInterface>hardware_interface/EffortJointInterface</hardwareInterface>
            <mechanicalReduction>1</mechanicalReduction>
        </actuator>
    </transmission>
    <transmission name="trans_a_torobo_gripper/mimic_joint">
        <type>transmission_interface/SimpleTransmission</type>
        <joint name="a_torobo_gripper/mimic_joint">
            <hardwareInterface>hardware_interface/EffortJointInterface</hardwareInterface>
        </joint>
        <actuator name="a_torobo_gripper/mimic_joint_motor">
            <hardwareInterface>hardware_interface/EffortJointInterface</hardwareInterface>
            <mechanicalReduction>1</mechanicalReduction>
        </actuator>
    </transmission>
    <transmission name="trans_b_torobo_gripper/finger_joint">
        <type>transmission_interface/SimpleTransmission</type>
        <joint name="b_torobo_gripper/finger_joint">
            <hardwareInterface>hardware_interface/EffortJointInterface</hardwareInterface>
        </joint>
        <actuator name="b_torobo_gripper/finger_joint_motor">
            <hardwareInterface>hardware_interface/EffortJointInterface</hardwareInterface>
            <mechanicalReduction>1</mechanicalReduction>
        </actuator>
    </transmission>
    <transmission name="trans_b_torobo_gripper/mimic_joint">
        <type>transmission_interface/SimpleTransmission</type>
        <joint name="b_torobo_gripper/mimic_joint">
            <hardwareInterface>hardware_interface/EffortJointInterface</hardwareInterface>
        </joint>
        <actuator name="b_torobo_gripper/mimic_joint_motor">
            <hardwareInterface>hardware_interface/EffortJointInterface</hardwareInterface>
            <mechanicalReduction>1</mechanicalReduction>
        </actuator>
    </transmission>
</robot>

